Workbook

Sheet LEYENDA
A1: 📋 LEYENDA DE ESTATUS — PROYECTO PAIG FASE II
A3: ESTATUS | B3: COLOR | C3: DESCRIPCIÓN | D3: ACCIÓN REQUERIDA
A4: INSTALADO - OPERANDO | B4: ● | C4: Instalación confirmada y equipo con señal activa. | D4: Ninguna — sitio completado.
A5: INSTALADO - SIN SEÑAL | B5: ● | C5: Equipo instalado pero sin señal. Ticket Mesa de Ayuda pendiente. | D5: Abrir/dar seguimiento a ticket MDA.
A6: EQUIPO EN ALMACÉN | B6: ● | C6: Equipo entregado al almacén, pendiente de instalación. | D6: Programar visita de instalación.
A7: PROGRAMADO | B7: ● | C7: Visita de instalación agendada. | D7: Confirmar fecha y asistir.
A8: VISITADO | B8: ● | C8: Se realizó visita pero no se pudo concluir la instalación. | D8: Registrar causa e reagendar.
A9: SIN INMUEBLE | B9: ● | C9: No existe instalación física en el sitio. | D9: Escalar para resolución con autoridades.
A11: 📌 INSTRUCCIONES DE USO
A12: 1. Cada responsable de GRT accede a su pestaña (ej. GRT Central).
A13: 2. Localiza el sitio correspondiente y selecciona el ESTATUS en la columna K usando la lista desplegable.
A14: 3. Registra la FECHA DE ACTUALIZACIÓN en la columna L (formato DD/MM/AAAA).
A15: 4. Agrega un COMENTARIO breve en la columna M si es necesario.
A16: 5. El DASHBOARD EJECUTIVO se actualiza automáticamente al guardar.
A17: 6. NO modificar columnas A-J (datos de identificación del sitio).
A18: 7. Compartir el archivo en SharePoint/Teams y activar co-autoría para edición simultánea.

Sheet DASHBOARD
A1: daniel
B2: TABLERO EJECUTIVO — PROYECTO PAIG FASE II
B3: Última actualización: 27/04/2026 | CFE Transmisión | 4,230 Sitios
B5: META TOTAL | D5: INSTALADOS OPERANDO | G5: EQ. EN ALMACÉN | J5: SITIOS CANCELADOS
B6: 4230 | D6: =CONSOLIDADO!C13+CONSOLIDADO!D13 -> 1289 | G6: =ENTREGA_ALMACÉN!F33-(CONSOLIDADO!C13+CONSOLIDADO!D13) -> 2571 | J6: =CONSOLIDADO!O13 -> 0
B7: sitios a instalar | D7: =TEXT((CONSOLIDADO!C13+CONSOLIDADO!D13)/4230,"0.0%")&" — del total" -> 30.5% — del total | G7: =TEXT((ENTREGA_ALMACÉN!F33-(CONSOLIDADO!C13+CONSOLIDADO!D13))/4230,"0.0%")&" — pend." -> 60.8% — pend. | J7: =TEXT(CONSOLIDADO!O13/4230,"0.0%")&" — del total" -> 0.0% — del total
B9: AVANCE POR GERENCIA REGIONAL DE TRANSMISIÓN
B10: GERENCIA | C10: TOTAL SITIOS | D10: INSTALADOS OPERANDO | E10: % INST. | F10: INSTALADO SIN SEÑAL | G10: VISITA FALLIDA | H10: SIN INMUEBLE | I10: EQ. EN ALMACÉN | J10: TOTAL ENTREGADO | K10: % EQ. ENTREG.
B11: GRT Central | C11: 1130 | D11: =IF(CONSOLIDADO!C5+CONSOLIDADO!D5=0,"—",CONSOLIDADO!C5+CONSOLIDADO!D5) -> 858 | E11: =IF(C11=0,"—",TEXT((CONSOLIDADO!C5+CONSOLIDADO!D5)/C11,"0.0%")) -> 75.9% | F11: =IF(CONSOLIDADO!D5=0,"—",CONSOLIDADO!D5) -> 89 | G11: =IF(CONSOLIDADO!G5=0,"—",CONSOLIDADO!G5) -> 20 | H11: =IF(CONSOLIDADO!H5=0,"—",CONSOLIDADO!H5) -> — | I11: =IF(CONSOLIDADO!E5=0,"—",CONSOLIDADO!E5) -> 265 | J11: =IF(CONSOLIDADO!C5+CONSOLIDADO!D5+CONSOLIDADO!E5=0,"—",CONSOLIDADO!C5+CONSOLIDADO!D5+CONSOLIDADO!E5) -> 1123 | K11: =IF(C11=0,"—",TEXT((CONSOLIDADO!C5+CONSOLIDADO!D5+CONSOLIDADO!E5)/C11,"0.0%")) -> 99.4%
B12: GRT Occidente | C12: 779 | D12: =IF(CONSOLIDADO!C6+CONSOLIDADO!D6=0,"—",CONSOLIDADO!C6+CONSOLIDADO!D6) -> 100 | E12: =IF(C12=0,"—",TEXT((CONSOLIDADO!C6+CONSOLIDADO!D6)/C12,"0.0%")) -> 12.8% | F12: =IF(CONSOLIDADO!D6=0,"—",CONSOLIDADO!D6) -> 20 | G12: =IF(CONSOLIDADO!G6=0,"—",CONSOLIDADO!G6) -> — | H12: =IF(CONSOLIDADO!H6=0,"—",CONSOLIDADO!H6) -> — | I12: =IF(CONSOLIDADO!E6=0,"—",CONSOLIDADO!E6) -> 631 | J12: =IF(CONSOLIDADO!C6+CONSOLIDADO!D6+CONSOLIDADO!E6=0,"—",CONSOLIDADO!C6+CONSOLIDADO!D6+CONSOLIDADO!E6) -> 731 | K12: =IF(C12=0,"—",TEXT((CONSOLIDADO!C6+CONSOLIDADO!D6+CONSOLIDADO!E6)/C12,"0.0%")) -> 93.8%
B13: GRT Oriente | C13: 395 | D13: =IF(CONSOLIDADO!C7+CONSOLIDADO!D7=0,"—",CONSOLIDADO!C7+CONSOLIDADO!D7) -> 84 | E13: =IF(C13=0,"—",TEXT((CONSOLIDADO!C7+CONSOLIDADO!D7)/C13,"0.0%")) -> 21.3% | F13: =IF(CONSOLIDADO!D7=0,"—",CONSOLIDADO!D7) -> 12 | G13: =IF(CONSOLIDADO!G7=0,"—",CONSOLIDADO!G7) -> — | H13: =IF(CONSOLIDADO!H7=0,"—",CONSOLIDADO!H7) -> — | I13: =IF(CONSOLIDADO!E7=0,"—",CONSOLIDADO!E7) -> 275 | J13: =IF(CONSOLIDADO!C7+CONSOLIDADO!D7+CONSOLIDADO!E7=0,"—",CONSOLIDADO!C7+CONSOLIDADO!D7+CONSOLIDADO!E7) -> 359 | K13: =IF(C13=0,"—",TEXT((CONSOLIDADO!C7+CONSOLIDADO!D7+CONSOLIDADO!E7)/C13,"0.0%")) -> 90.9%
B14: GRT Valle de México | C14: 735 | D14: =IF(CONSOLIDADO!C8+CONSOLIDADO!D8=0,"—",CONSOLIDADO!C8+CONSOLIDADO!D8) -> 77 | E14: =IF(C14=0,"—",TEXT((CONSOLIDADO!C8+CONSOLIDADO!D8)/C14,"0.0%")) -> 10.5% | F14: =IF(CONSOLIDADO!D8=0,"—",CONSOLIDADO!D8) -> 3 | G14: =IF(CONSOLIDADO!G8=0,"—",CONSOLIDADO!G8) -> — | H14: =IF(CONSOLIDADO!H8=0,"—",CONSOLIDADO!H8) -> — | I14: =IF(CONSOLIDADO!E8=0,"—",CONSOLIDADO!E8) -> 460 | J14: =IF(CONSOLIDADO!C8+CONSOLIDADO!D8+CONSOLIDADO!E8=0,"—",CONSOLIDADO!C8+CONSOLIDADO!D8+CONSOLIDADO!E8) -> 537 | K14: =IF(C14=0,"—",TEXT((CONSOLIDADO!C8+CONSOLIDADO!D8+CONSOLIDADO!E8)/C14,"0.0%")) -> 73.1%
B15: GRT Noroeste | C15: 367 | D15: =IF(CONSOLIDADO!C9+CONSOLIDADO!D9=0,"—",CONSOLIDADO!C9+CONSOLIDADO!D9) -> 63 | E15: =IF(C15=0,"—",TEXT((CONSOLIDADO!C9+CONSOLIDADO!D9)/C15,"0.0%")) -> 17.2% | F15: =IF(CONSOLIDADO!D9=0,"—",CONSOLIDADO!D9) -> 3 | G15: =IF(CONSOLIDADO!G9=0,"—",CONSOLIDADO!G9) -> — | H15: =IF(CONSOLIDADO!H9=0,"—",CONSOLIDADO!H9) -> 2 | I15: =IF(CONSOLIDADO!E9=0,"—",CONSOLIDADO!E9) -> 284 | J15: =IF(CONSOLIDADO!C9+CONSOLIDADO!D9+CONSOLIDADO!E9=0,"—",CONSOLIDADO!C9+CONSOLIDADO!D9+CONSOLIDADO!E9) -> 347 | K15: =IF(C15=0,"—",TEXT((CONSOLIDADO!C9+CONSOLIDADO!D9+CONSOLIDADO!E9)/C15,"0.0%")) -> 94.6%
B16: GRT Norte | C16: 291 | D16: =IF(CONSOLIDADO!C10+CONSOLIDADO!D10=0,"—",CONSOLIDADO!C10+CONSOLIDADO!D10) -> 22 | E16: =IF(C16=0,"—",TEXT((CONSOLIDADO!C10+CONSOLIDADO!D10)/C16,"0.0%")) -> 7.6% | F16: =IF(CONSOLIDADO!D10=0,"—",CONSOLIDADO!D10) -> 3 | G16: =IF(CONSOLIDADO!G10=0,"—",CONSOLIDADO!G10) -> — | H16: =IF(CONSOLIDADO!H10=0,"—",CONSOLIDADO!H10) -> — | I16: =IF(CONSOLIDADO!E10=0,"—",CONSOLIDADO!E10) -> 269 | J16: =IF(CONSOLIDADO!C10+CONSOLIDADO!D10+CONSOLIDADO!E10=0,"—",CONSOLIDADO!C10+CONSOLIDADO!D10+CONSOLIDADO!E10) -> 291 | K16: =IF(C16=0,"—",TEXT((CONSOLIDADO!C10+CONSOLIDADO!D10+CONSOLIDADO!E10)/C16,"0.0%")) -> 100.0%
B17: GRT Noreste | C17: 257 | D17: =IF(CONSOLIDADO!C11+CONSOLIDADO!D11=0,"—",CONSOLIDADO!C11+CONSOLIDADO!D11) -> 42 | E17: =IF(C17=0,"—",TEXT((CONSOLIDADO!C11+CONSOLIDADO!D11)/C17,"0.0%")) -> 16.3% | F17: =IF(CONSOLIDADO!D11=0,"—",CONSOLIDADO!D11) -> — | G17: =IF(CONSOLIDADO!G11=0,"—",CONSOLIDADO!G11) -> 1 | H17: =IF(CONSOLIDADO!H11=0,"—",CONSOLIDADO!H11) -> 1 | I17: =IF(CONSOLIDADO!E11=0,"—",CONSOLIDADO!E11) -> 203 | J17: =IF(CONSOLIDADO!C11+CONSOLIDADO!D11+CONSOLIDADO!E11=0,"—",CONSOLIDADO!C11+CONSOLIDADO!D11+CONSOLIDADO!E11) -> 245 | K17: =IF(C17=0,"—",TEXT((CONSOLIDADO!C11+CONSOLIDADO!D11+CONSOLIDADO!E11)/C17,"0.0%")) -> 95.3%
B18: GRT Baja California | C18: 276 | D18: =IF(CONSOLIDADO!C12+CONSOLIDADO!D12=0,"—",CONSOLIDADO!C12+CONSOLIDADO!D12) -> 43 | E18: =IF(C18=0,"—",TEXT((CONSOLIDADO!C12+CONSOLIDADO!D12)/C18,"0.0%")) -> 15.6% | F18: =IF(CONSOLIDADO!D12=0,"—",CONSOLIDADO!D12) -> 14 | G18: =IF(CONSOLIDADO!G12=0,"—",CONSOLIDADO!G12) -> — | H18: =IF(CONSOLIDADO!H12=0,"—",CONSOLIDADO!H12) -> — | I18: =IF(CONSOLIDADO!E12=0,"—",CONSOLIDADO!E12) -> 184 | J18: =IF(CONSOLIDADO!C12+CONSOLIDADO!D12+CONSOLIDADO!E12=0,"—",CONSOLIDADO!C12+CONSOLIDADO!D12+CONSOLIDADO!E12) -> 227 | K18: =IF(C18=0,"—",TEXT((CONSOLIDADO!C12+CONSOLIDADO!D12+CONSOLIDADO!E12)/C18,"0.0%")) -> 82.2%
B19: TOTAL | C19: 4230 | D19: =CONSOLIDADO!C13+CONSOLIDADO!D13 -> 1289 | E19: =TEXT(D19/C19,"0.0%") -> 30.5% | F19: =IF(CONSOLIDADO!D13=0,"—",CONSOLIDADO!D13) -> 144 | G19: =IF(CONSOLIDADO!G13=0,"—",CONSOLIDADO!G13) -> 21 | H19: =IF(CONSOLIDADO!H13=0,"—",CONSOLIDADO!H13) -> 3 | I19: =CONSOLIDADO!E13 -> 2571 | J19: =CONSOLIDADO!C13+CONSOLIDADO!D13+CONSOLIDADO!E13 -> 3860 | K19: =TEXT(J19/C19,"0.0%") -> 91.3%
B21: CFE Transmisión | PAIG Fase II | Meta: 4,230 sitios | Límite GRT: 15 Jun 2026 | Cierre: 30 Jun 2026

Sheet RESUMEN_EJECUTIVO
B2: TABLERO EJECUTIVO — PROYECTO PAIG FASE II
B3: =TEXT(TODAY(),"DD/MM/YYYY")&" | CFE Transmisión | 4,230 Sitios" -> 12/05/2026 | CFE Transmisión | 4,230 Sitios
B5: EQUIPOS ASIGNADOS | D5: EQUIPOS ENTREGADOS | F5: INSTALADOS (Op+SS+Vis) | H5: EQ. EN ALMACÉN (Entr. - Inst.) | J5: CANCELADOS
B6: =CONSOLIDADO!B13 -> 4230 | D6: =ENTREGA_ALMACÉN!F33 -> 3860 | F6: =CONSOLIDADO!C13+CONSOLIDADO!D13+CONSOLIDADO!G13 -> 1310 | H6: =ENTREGA_ALMACÉN!F33-(CONSOLIDADO!C13+CONSOLIDADO!D13+CONSOLIDADO!G13) -> 2550 | J6: =CONSOLIDADO!O13 -> 0
B7: "100% — meta total" | D7: =TEXT(ENTREGA_ALMACÉN!F33/CONSOLIDADO!B13,"0.00%")&" — del asignado" -> 91.25% — del asignado | F7: =TEXT((CONSOLIDADO!C13+CONSOLIDADO!D13+CONSOLIDADO!G13)/CONSOLIDADO!B13,"0.00%")&" — del asignado" -> 30.97% — del asignado | H7: =TEXT((ENTREGA_ALMACÉN!F33-(CONSOLIDADO!C13+CONSOLIDADO!D13+CONSOLIDADO!G13))/ENTREGA_ALMACÉN!F33,"0.00%")&" — del entregado" -> 66.06% — del entregado | J7: =TEXT(CONSOLIDADO!O13/CONSOLIDADO!B13,"0.00%")&" — del asignado" -> 0.00% — del asignado
B9: AVANCE POR GERENCIA REGIONAL DE TRANSMISIÓN
B10: GERENCIA | C10: TOTAL SITIOS | D10: CANCELADOS | E10: INSTALADOS (Op+SS+Vis) | F10: % INST. /ASIGNADO | G10: TOTAL ENTREGADO | H10: % ENTR. /ASIGNADO | I10: EQ. EN ALMACÉN | J10: % ALM. /ENTREGADO
B11: =CONSOLIDADO!A5 -> GRT Central | C11: =CONSOLIDADO!B5 -> 1130 | D11: =CONSOLIDADO!O5 -> 0 | E11: =CONSOLIDADO!C5+CONSOLIDADO!D5+CONSOLIDADO!G5 -> 878 | F11: =IF(CONSOLIDADO!B5=0,0,(CONSOLIDADO!C5+CONSOLIDADO!D5+CONSOLIDADO!G5)/CONSOLIDADO!B5) -> 0.77699115 | G11: =ENTREGA_ALMACÉN!C37 -> 1123 | H11: =IF(CONSOLIDADO!B5=0,0,ENTREGA_ALMACÉN!C37/CONSOLIDADO!B5) -> 0.99380531 | I11: =MAX(0,ENTREGA_ALMACÉN!C37-(CONSOLIDADO!C5+CONSOLIDADO!D5+CONSOLIDADO!G5)) -> 245 | J11: =IF(ENTREGA_ALMACÉN!C37=0,0,MAX(0,ENTREGA_ALMACÉN!C37-(CONSOLIDADO!C5+CONSOLIDADO!D5+CONSOLIDADO!G5))/ENTREGA_ALMACÉN!C37) -> 0.21816563
B12: =CONSOLIDADO!A6 -> GRT Occidente | C12: =CONSOLIDADO!B6 -> 779 | D12: =CONSOLIDADO!O6 -> 0 | E12: =CONSOLIDADO!C6+CONSOLIDADO!D6+CONSOLIDADO!G6 -> 100 | F12: =IF(CONSOLIDADO!B6=0,0,(CONSOLIDADO!C6+CONSOLIDADO!D6+CONSOLIDADO!G6)/CONSOLIDADO!B6) -> 0.1283697 | G12: =ENTREGA_ALMACÉN!C38 -> 731 | H12: =IF(CONSOLIDADO!B6=0,0,ENTREGA_ALMACÉN!C38/CONSOLIDADO!B6) -> 0.93838254 | I12: =MAX(0,ENTREGA_ALMACÉN!C38-(CONSOLIDADO!C6+CONSOLIDADO!D6+CONSOLIDADO!G6)) -> 631 | J12: =IF(ENTREGA_ALMACÉN!C38=0,0,MAX(0,ENTREGA_ALMACÉN!C38-(CONSOLIDADO!C6+CONSOLIDADO!D6+CONSOLIDADO!G6))/ENTREGA_ALMACÉN!C38) -> 0.86320109
B13: =CONSOLIDADO!A7 -> GRT Oriente | C13: =CONSOLIDADO!B7 -> 395 | D13: =CONSOLIDADO!O7 -> 0 | E13: =CONSOLIDADO!C7+CONSOLIDADO!D7+CONSOLIDADO!G7 -> 84 | F13: =IF(CONSOLIDADO!B7=0,0,(CONSOLIDADO!C7+CONSOLIDADO!D7+CONSOLIDADO!G7)/CONSOLIDADO!B7) -> 0.21265823 | G13: =ENTREGA_ALMACÉN!C39 -> 359 | H13: =IF(CONSOLIDADO!B7=0,0,ENTREGA_ALMACÉN!C39/CONSOLIDADO!B7) -> 0.90886076 | I13: =MAX(0,ENTREGA_ALMACÉN!C39-(CONSOLIDADO!C7+CONSOLIDADO!D7+CONSOLIDADO!G7)) -> 275 | J13: =IF(ENTREGA_ALMACÉN!C39=0,0,MAX(0,ENTREGA_ALMACÉN!C39-(CONSOLIDADO!C7+CONSOLIDADO!D7+CONSOLIDADO!G7))/ENTREGA_ALMACÉN!C39) -> 0.76601671
B14: =CONSOLIDADO!A8 -> GRT Valle de México | C14: =CONSOLIDADO!B8 -> 735 | D14: =CONSOLIDADO!O8 -> 0 | E14: =CONSOLIDADO!C8+CONSOLIDADO!D8+CONSOLIDADO!G8 -> 77 | F14: =IF(CONSOLIDADO!B8=0,0,(CONSOLIDADO!C8+CONSOLIDADO!D8+CONSOLIDADO!G8)/CONSOLIDADO!B8) -> 0.1047619 | G14: =ENTREGA_ALMACÉN!C40 -> 537 | H14: =IF(CONSOLIDADO!B8=0,0,ENTREGA_ALMACÉN!C40/CONSOLIDADO!B8) -> 0.73061224 | I14: =MAX(0,ENTREGA_ALMACÉN!C40-(CONSOLIDADO!C8+CONSOLIDADO!D8+CONSOLIDADO!G8)) -> 460 | J14: =IF(ENTREGA_ALMACÉN!C40=0,0,MAX(0,ENTREGA_ALMACÉN!C40-(CONSOLIDADO!C8+CONSOLIDADO!D8+CONSOLIDADO!G8))/ENTREGA_ALMACÉN!C40) -> 0.8566108
B15: =CONSOLIDADO!A9 -> GRT Noroeste | C15: =CONSOLIDADO!B9 -> 367 | D15: =CONSOLIDADO!O9 -> 0 | E15: =CONSOLIDADO!C9+CONSOLIDADO!D9+CONSOLIDADO!G9 -> 63 | F15: =IF(CONSOLIDADO!B9=0,0,(CONSOLIDADO!C9+CONSOLIDADO!D9+CONSOLIDADO!G9)/CONSOLIDADO!B9) -> 0.17166213 | G15: =ENTREGA_ALMACÉN!C41 -> 347 | H15: =IF(CONSOLIDADO!B9=0,0,ENTREGA_ALMACÉN!C41/CONSOLIDADO!B9) -> 0.94550409 | I15: =MAX(0,ENTREGA_ALMACÉN!C41-(CONSOLIDADO!C9+CONSOLIDADO!D9+CONSOLIDADO!G9)) -> 284 | J15: =IF(ENTREGA_ALMACÉN!C41=0,0,MAX(0,ENTREGA_ALMACÉN!C41-(CONSOLIDADO!C9+CONSOLIDADO!D9+CONSOLIDADO!G9))/ENTREGA_ALMACÉN!C41) -> 0.8184438
B16: =CONSOLIDADO!A10 -> GRT Norte | C16: =CONSOLIDADO!B10 -> 291 | D16: =CONSOLIDADO!O10 -> 0 | E16: =CONSOLIDADO!C10+CONSOLIDADO!D10+CONSOLIDADO!G10 -> 22 | F16: =IF(CONSOLIDADO!B10=0,0,(CONSOLIDADO!C10+CONSOLIDADO!D10+CONSOLIDADO!G10)/CONSOLIDADO!B10) -> 0.075601375 | G16: =ENTREGA_ALMACÉN!C42 -> 291 | H16: =IF(CONSOLIDADO!B10=0,0,ENTREGA_ALMACÉN!C42/CONSOLIDADO!B10) -> 1 | I16: =MAX(0,ENTREGA_ALMACÉN!C42-(CONSOLIDADO!C10+CONSOLIDADO!D10+CONSOLIDADO!G10)) -> 269 | J16: =IF(ENTREGA_ALMACÉN!C42=0,0,MAX(0,ENTREGA_ALMACÉN!C42-(CONSOLIDADO!C10+CONSOLIDADO!D10+CONSOLIDADO!G10))/ENTREGA_ALMACÉN!C42) -> 0.92439863
B17: =CONSOLIDADO!A11 -> GRT Noreste | C17: =CONSOLIDADO!B11 -> 257 | D17: =CONSOLIDADO!O11 -> 0 | E17: =CONSOLIDADO!C11+CONSOLIDADO!D11+CONSOLIDADO!G11 -> 43 | F17: =IF(CONSOLIDADO!B11=0,0,(CONSOLIDADO!C11+CONSOLIDADO!D11+CONSOLIDADO!G11)/CONSOLIDADO!B11) -> 0.16731518 | G17: =ENTREGA_ALMACÉN!C43 -> 245 | H17: =IF(CONSOLIDADO!B11=0,0,ENTREGA_ALMACÉN!C43/CONSOLIDADO!B11) -> 0.95330739 | I17: =MAX(0,ENTREGA_ALMACÉN!C43-(CONSOLIDADO!C11+CONSOLIDADO!D11+CONSOLIDADO!G11)) -> 202 | J17: =IF(ENTREGA_ALMACÉN!C43=0,0,MAX(0,ENTREGA_ALMACÉN!C43-(CONSOLIDADO!C11+CONSOLIDADO!D11+CONSOLIDADO!G11))/ENTREGA_ALMACÉN!C43) -> 0.8244898
B18: =CONSOLIDADO!A12 -> GRT Baja California | C18: =CONSOLIDADO!B12 -> 276 | D18: =CONSOLIDADO!O12 -> 0 | E18: =CONSOLIDADO!C12+CONSOLIDADO!D12+CONSOLIDADO!G12 -> 43 | F18: =IF(CONSOLIDADO!B12=0,0,(CONSOLIDADO!C12+CONSOLIDADO!D12+CONSOLIDADO!G12)/CONSOLIDADO!B12) -> 0.1557971 | G18: =ENTREGA_ALMACÉN!C44 -> 227 | H18: =IF(CONSOLIDADO!B12=0,0,ENTREGA_ALMACÉN!C44/CONSOLIDADO!B12) -> 0.82246377 | I18: =MAX(0,ENTREGA_ALMACÉN!C44-(CONSOLIDADO!C12+CONSOLIDADO!D12+CONSOLIDADO!G12)) -> 184 | J18: =IF(ENTREGA_ALMACÉN!C44=0,0,MAX(0,ENTREGA_ALMACÉN!C44-(CONSOLIDADO!C12+CONSOLIDADO!D12+CONSOLIDADO!G12))/ENTREGA_ALMACÉN!C44) -> 0.81057269
B19: TOTAL GENERAL | C19: =CONSOLIDADO!B13 -> 4230 | D19: =CONSOLIDADO!O13 -> 0 | E19: =CONSOLIDADO!C13+CONSOLIDADO!D13+CONSOLIDADO!G13 -> 1310 | F19: =IF(CONSOLIDADO!B13=0,0,(CONSOLIDADO!C13+CONSOLIDADO!D13+CONSOLIDADO!G13)/CONSOLIDADO!B13) -> 0.30969267 | G19: =ENTREGA_ALMACÉN!F33 -> 3860 | H19: =IF(CONSOLIDADO!B13=0,0,ENTREGA_ALMACÉN!F33/CONSOLIDADO!B13) -> 0.91252955 | I19: =MAX(0,ENTREGA_ALMACÉN!F33-(CONSOLIDADO!C13+CONSOLIDADO!D13+CONSOLIDADO!G13)) -> 2550 | J19: =IF(ENTREGA_ALMACÉN!F33=0,0,MAX(0,ENTREGA_ALMACÉN!F33-(CONSOLIDADO!C13+CONSOLIDADO!D13+CONSOLIDADO!G13))/ENTREGA_ALMACÉN!F33) -> 0.66062176
B21: CFE Transmisión | PAIG Fase II | Meta: 4,230 sitios | Límite GRT: 15 Jun 2026 | Cierre: 30 Jun 2026

Sheet REPORTE_JEFE
B2: REPORTE EJECUTIVO — PROYECTO PAIG FASE II
B3: =TEXT(TODAY(),"DD/MM/YYYY")&" | CFE Transmisión | 4,230 Sitios" -> 12/05/2026 | CFE Transmisión | 4,230 Sitios
B5: EQUIPOS ASIGNADOS | C5: EQUIPOS ENTREGADOS | D5: EQUIPOS PENDIENTES DE ENTREGA | E5: % EQUIPOS ENTREGADOS | F5: INSTALADOS | G5: % INSTALADOS
G6: ASIGNADOS | H6: ENTREGADOS
B8: =CONSOLIDADO!B13 -> 4230 | C8: =ENTREGA_ALMACÉN!F33 -> 3860 | D8: =CONSOLIDADO!B13-ENTREGA_ALMACÉN!F33 -> 370 | E8: =TEXT(ENTREGA_ALMACÉN!F33/CONSOLIDADO!B13,"0.00%") -> 91.25% | F8: =CONSOLIDADO!C13+CONSOLIDADO!D13+CONSOLIDADO!G13 -> 1310 | G8: =TEXT((CONSOLIDADO!C13+CONSOLIDADO!D13+CONSOLIDADO!G13)/CONSOLIDADO!B13,"0.00%") -> 30.97% | H8: =TEXT((CONSOLIDADO!C13+CONSOLIDADO!D13+CONSOLIDADO!G13)/ENTREGA_ALMACÉN!F33,"0.00%") -> 33.94%
B9: DESGLOSE POR GERENCIA REGIONAL DE TRANSMISIÓN
B10: GERENCIA REGIONAL | C10: EQUIPOS ASIGNADOS | D10: EQUIPOS ENTREGADOS | E10: EQUIPOS PENDIENTES | F10: % EQUIPOS ENTREGADOS | G10: INSTALADOS | H10: % INST. ASIGNADOS | I10: % INST. ENTREGADOS
B11: =CONSOLIDADO!A5 -> GRT Central | C11: =CONSOLIDADO!B5 -> 1130 | D11: =ENTREGA_ALMACÉN!C37 -> 1123 | E11: =CONSOLIDADO!B5-ENTREGA_ALMACÉN!C37 -> 7 | F11: =IF(CONSOLIDADO!B5=0,0,ENTREGA_ALMACÉN!C37/CONSOLIDADO!B5) -> 0.99380531 | G11: =CONSOLIDADO!C5+CONSOLIDADO!D5+CONSOLIDADO!G5 -> 878 | H11: =IF(CONSOLIDADO!B5=0,0,(CONSOLIDADO!C5+CONSOLIDADO!D5+CONSOLIDADO!G5)/CONSOLIDADO!B5) -> 0.77699115 | I11: =IF(ENTREGA_ALMACÉN!C37=0,0,(CONSOLIDADO!C5+CONSOLIDADO!D5+CONSOLIDADO!G5)/ENTREGA_ALMACÉN!C37) -> 0.78183437
B12: =CONSOLIDADO!A6 -> GRT Occidente | C12: =CONSOLIDADO!B6 -> 779 | D12: =ENTREGA_ALMACÉN!C38 -> 731 | E12: =CONSOLIDADO!B6-ENTREGA_ALMACÉN!C38 -> 48 | F12: =IF(CONSOLIDADO!B6=0,0,ENTREGA_ALMACÉN!C38/CONSOLIDADO!B6) -> 0.93838254 | G12: =CONSOLIDADO!C6+CONSOLIDADO!D6+CONSOLIDADO!G6 -> 100 | H12: =IF(CONSOLIDADO!B6=0,0,(CONSOLIDADO!C6+CONSOLIDADO!D6+CONSOLIDADO!G6)/CONSOLIDADO!B6) -> 0.1283697 | I12: =IF(ENTREGA_ALMACÉN!C38=0,0,(CONSOLIDADO!C6+CONSOLIDADO!D6+CONSOLIDADO!G6)/ENTREGA_ALMACÉN!C38) -> 0.13679891
B13: =CONSOLIDADO!A7 -> GRT Oriente | C13: =CONSOLIDADO!B7 -> 395 | D13: =ENTREGA_ALMACÉN!C39 -> 359 | E13: =CONSOLIDADO!B7-ENTREGA_ALMACÉN!C39 -> 36 | F13: =IF(CONSOLIDADO!B7=0,0,ENTREGA_ALMACÉN!C39/CONSOLIDADO!B7) -> 0.90886076 | G13: =CONSOLIDADO!C7+CONSOLIDADO!D7+CONSOLIDADO!G7 -> 84 | H13: =IF(CONSOLIDADO!B7=0,0,(CONSOLIDADO!C7+CONSOLIDADO!D7+CONSOLIDADO!G7)/CONSOLIDADO!B7) -> 0.21265823 | I13: =IF(ENTREGA_ALMACÉN!C39=0,0,(CONSOLIDADO!C7+CONSOLIDADO!D7+CONSOLIDADO!G7)/ENTREGA_ALMACÉN!C39) -> 0.23398329
B14: =CONSOLIDADO!A8 -> GRT Valle de México | C14: =CONSOLIDADO!B8 -> 735 | D14: =ENTREGA_ALMACÉN!C40 -> 537 | E14: =CONSOLIDADO!B8-ENTREGA_ALMACÉN!C40 -> 198 | F14: =IF(CONSOLIDADO!B8=0,0,ENTREGA_ALMACÉN!C40/CONSOLIDADO!B8) -> 0.73061224 | G14: =CONSOLIDADO!C8+CONSOLIDADO!D8+CONSOLIDADO!G8 -> 77 | H14: =IF(CONSOLIDADO!B8=0,0,(CONSOLIDADO!C8+CONSOLIDADO!D8+CONSOLIDADO!G8)/CONSOLIDADO!B8) -> 0.1047619 | I14: =IF(ENTREGA_ALMACÉN!C40=0,0,(CONSOLIDADO!C8+CONSOLIDADO!D8+CONSOLIDADO!G8)/ENTREGA_ALMACÉN!C40) -> 0.1433892
B15: =CONSOLIDADO!A9 -> GRT Noroeste | C15: =CONSOLIDADO!B9 -> 367 | D15: =ENTREGA_ALMACÉN!C41 -> 347 | E15: =CONSOLIDADO!B9-ENTREGA_ALMACÉN!C41 -> 20 | F15: =IF(CONSOLIDADO!B9=0,0,ENTREGA_ALMACÉN!C41/CONSOLIDADO!B9) -> 0.94550409 | G15: =CONSOLIDADO!C9+CONSOLIDADO!D9+CONSOLIDADO!G9 -> 63 | H15: =IF(CONSOLIDADO!B9=0,0,(CONSOLIDADO!C9+CONSOLIDADO!D9+CONSOLIDADO!G9)/CONSOLIDADO!B9) -> 0.17166213 | I15: =IF(ENTREGA_ALMACÉN!C41=0,0,(CONSOLIDADO!C9+CONSOLIDADO!D9+CONSOLIDADO!G9)/ENTREGA_ALMACÉN!C41) -> 0.1815562
B16: =CONSOLIDADO!A10 -> GRT Norte | C16: =CONSOLIDADO!B10 -> 291 | D16: =ENTREGA_ALMACÉN!C42 -> 291 | E16: =CONSOLIDADO!B10-ENTREGA_ALMACÉN!C42 -> 0 | F16: =IF(CONSOLIDADO!B10=0,0,ENTREGA_ALMACÉN!C42/CONSOLIDADO!B10) -> 1 | G16: =CONSOLIDADO!C10+CONSOLIDADO!D10+CONSOLIDADO!G10 -> 22 | H16: =IF(CONSOLIDADO!B10=0,0,(CONSOLIDADO!C10+CONSOLIDADO!D10+CONSOLIDADO!G10)/CONSOLIDADO!B10) -> 0.075601375 | I16: =IF(ENTREGA_ALMACÉN!C42=0,0,(CONSOLIDADO!C10+CONSOLIDADO!D10+CONSOLIDADO!G10)/ENTREGA_ALMACÉN!C42) -> 0.075601375
B17: =CONSOLIDADO!A11 -> GRT Noreste | C17: =CONSOLIDADO!B11 -> 257 | D17: =ENTREGA_ALMACÉN!C43 -> 245 | E17: =CONSOLIDADO!B11-ENTREGA_ALMACÉN!C43 -> 12 | F17: =IF(CONSOLIDADO!B11=0,0,ENTREGA_ALMACÉN!C43/CONSOLIDADO!B11) -> 0.95330739 | G17: =CONSOLIDADO!C11+CONSOLIDADO!D11+CONSOLIDADO!G11 -> 43 | H17: =IF(CONSOLIDADO!B11=0,0,(CONSOLIDADO!C11+CONSOLIDADO!D11+CONSOLIDADO!G11)/CONSOLIDADO!B11) -> 0.16731518 | I17: =IF(ENTREGA_ALMACÉN!C43=0,0,(CONSOLIDADO!C11+CONSOLIDADO!D11+CONSOLIDADO!G11)/ENTREGA_ALMACÉN!C43) -> 0.1755102
B18: =CONSOLIDADO!A12 -> GRT Baja California | C18: =CONSOLIDADO!B12 -> 276 | D18: =ENTREGA_ALMACÉN!C44 -> 227 | E18: =CONSOLIDADO!B12-ENTREGA_ALMACÉN!C44 -> 49 | F18: =IF(CONSOLIDADO!B12=0,0,ENTREGA_ALMACÉN!C44/CONSOLIDADO!B12) -> 0.82246377 | G18: =CONSOLIDADO!C12+CONSOLIDADO!D12+CONSOLIDADO!G12 -> 43 | H18: =IF(CONSOLIDADO!B12=0,0,(CONSOLIDADO!C12+CONSOLIDADO!D12+CONSOLIDADO!G12)/CONSOLIDADO!B12) -> 0.1557971 | I18: =IF(ENTREGA_ALMACÉN!C44=0,0,(CONSOLIDADO!C12+CONSOLIDADO!D12+CONSOLIDADO!G12)/ENTREGA_ALMACÉN!C44) -> 0.18942731
B19: TOTAL GENERAL | C19: =CONSOLIDADO!B13 -> 4230 | D19: =ENTREGA_ALMACÉN!F33 -> 3860 | E19: =CONSOLIDADO!B13-ENTREGA_ALMACÉN!F33 -> 370 | F19: =IF(CONSOLIDADO!B13=0,0,ENTREGA_ALMACÉN!F33/CONSOLIDADO!B13) -> 0.91252955 | G19: =CONSOLIDADO!C13+CONSOLIDADO!D13+CONSOLIDADO!G13 -> 1310 | H19: =IF(CONSOLIDADO!B13=0,0,(CONSOLIDADO!C13+CONSOLIDADO!D13+CONSOLIDADO!G13)/CONSOLIDADO!B13) -> 0.30969267 | I19: =IF(ENTREGA_ALMACÉN!F33=0,0,(CONSOLIDADO!C13+CONSOLIDADO!D13+CONSOLIDADO!G13)/ENTREGA_ALMACÉN!F33) -> 0.33937824
B22: CFE Transmisión | PAIG Fase II | Meta: 4,230 sitios | Límite GRT: 15 Jun 2026 | Cierre: 30 Jun 2026

Sheet BD_CONTROL
A1: BASE DE DATOS CONTROL — PROYECTO PAIG FASE II | Instalación de Internet en 4,230 Sitios
A3: ⚠ NO modificar columnas A–J | Solo actualizar: K (Estatus) · L (Fecha) · M (Comentarios)
A5: CLAVE | B5: ID PUNTO | C5: NOMBRE DEL SITIO | D5: ESTADO | E5: MUNICIPIO | F5: LOCALIDAD | G5: ÁMBITO | H5: GERENCIA (GRT) | I5: ALMACÉN | J5: INSTITUCIÓN | K5: ▼ ESTATUS | L5: FECHA ACTUALIZACIÓN | M5: COMENTARIOS
A6: 02DTV0005P | B6: 513069 | C6: TELESECUNDARIA 101 INDE CAR TIJUANA | D6: BAJA CALIFORNIA | E6: TIJUANA | F6: MESA DE OTAY | G6: URBANO | H6: GRT Baja California | I6: ALMACEN ZT VALLE | J6: TELEESCUELA
A7: 02DTV0006O | B7: 513511 | C7: TELESECUNDARIA 102 | D7: BAJA CALIFORNIA | E7: ENSENADA | F7: ZARAHEMLA | G7: RURAL | H7: GRT Baja California | I7: ALMACEN ZT VALLE | J7: TELEESCUELA
A8: 02DTV0009L | B8: 513470 | C8: TELESECUNDARIA 105 | D8: BAJA CALIFORNIA | E8: ENSENADA | F8: MANEADERO | G8: RURAL | H8: GRT Baja California | I8: ALMACEN ZT VALLE | J8: TELEESCUELA
A9: 02DTV0011Z | B9: 513507 | C9: TELESECUNDARIA 107 | D9: BAJA CALIFORNIA | E9: ENSENADA | F9: EL ROSARIO DE ABAJO | G9: RURAL | H9: GRT Baja California | I9: ALMACEN ZT VALLE | J9: TELEESCUELA
A10: 02DTV0012Z | B10: 513515 | C10: TELESECUNDARIA 108 | D10: BAJA CALIFORNIA | E10: ENSENADA | F10: EJIDO VENUSTIANO CARRANZA | G10: RURAL | H10: GRT Baja California | I10: ALMACEN ZT VALLE | J10: TELEESCUELA
A11: 02DTV0013Y | B11: 513004 | C11: TELESECUNDARIA 109 | D11: BAJA CALIFORNIA | E11: TIJUANA | F11: TIJUANA | G11: RURAL | H11: GRT Baja California | I11: ALMACEN ZT VALLE | J11: TELEESCUELA | K11: Instalado - Operando | L11: 46150
A12: 02DTV0014X | B12: 513501 | C12: TELESECUNDARIA FEDERAL 110 | D12: BAJA CALIFORNIA | E12: TECATE | F12: TECATE | G12: URBANO | H12: GRT Baja California | I12: ALMACEN ZT VALLE | J12: TELEESCUELA
A13: 02DTV0015W | B13: 513478 | C13: TELESECUNDARIA 111 | D13: BAJA CALIFORNIA | E13: ENSENADA | F13: SAN CARLOS | G13: RURAL | H13: GRT Baja California | I13: ALMACEN ZT VALLE | J13: TELEESCUELA
A14: 02DTV0016V | B14: 513509 | C14: TELESECUNDARIA 112 | D14: BAJA CALIFORNIA | E14: ENSENADA | F14: EJIDO RODOLFO SANCHEZ TABOADA | G14: RURAL | H14: GRT Baja California | I14: ALMACEN ZT VALLE | J14: TELEESCUELA
A15: 02DTV0017U | B15: 513466 | C15: TELESECUNDARIA 113 | D15: BAJA CALIFORNIA | E15: ENSENADA | F15: EJIDO BENITO JUAREZ | G15: RURAL | H15: GRT Baja California | I15: ALMACEN ZT VALLE | J15: TELEESCUELA
A16: 02DTV0019S | B16: 513428 | C16: TETELESECUNDARIA 115 | D16: BAJA CALIFORNIA | E16: TIJUANA | F16: TIJUANA | G16: RURAL | H16: GRT Baja California | I16: ALMACEN ZT VALLE | J16: TELEESCUELA
A17: 02DTV0021G | B17: 513535 | C17: ESCUELA TELESECUNDARIA 117 | D17: BAJA CALIFORNIA | E17: TIJUANA | F17: VALLE IMPERIAL | G17: RURAL | H17: GRT Baja California | I17: ALMACEN ZT VALLE | J17: TELEESCUELA
A18: 02DTV0022F | B18: 513014 | C18: TELESECUNDARIA 118 | D18: BAJA CALIFORNIA | E18: TIJUANA | F18: EJIDO LAZARO CARDENAS | G18: RURAL | H18: GRT Baja California | I18: ALMACEN ZT VALLE | J18: TELEESCUELA
A19: 02DTV0023E | B19: 513493 | C19: TELESECUNDARIA 119 | D19: BAJA CALIFORNIA | E19: PLAYAS DE ROSARITO | F19: PLAYAS DE ROSARITO | G19: RURAL | H19: GRT Baja California | I19: ALMACEN ZT VALLE | J19: TELEESCUELA
A20: 02ETK0001M | B20: 513438 | C20: TELEBACHILLERATO COMUNITARIO VILLA ZAPATA | D20: BAJA CALIFORNIA | E20: MEXICALI | F20: VILLA ZAPATA MESA ARENOSA DE ANDRADE | G20: RURAL | H20: GRT Baja California | I20: ALMACEN ZT VALLE | J20: TELEESCUELA
A21: 02ETK0003K | B21: 513421 | C21: TELEBACHILLERATO COMUNITARIO DE LAS CRUCES 3 | D21: BAJA CALIFORNIA | E21: TIJUANA | F21: TIJUANA | G21: URBANO | H21: GRT Baja California | I21: ALMACEN ZT VALLE | J21: TELEESCUELA
A22: 02ETK0004J | B22: 513474 | C22: TELEBACHILLERATO COMUNITARIO GOMEZ MORIN | D22: BAJA CALIFORNIA | E22: ENSENADA | F22: ENSENADA | G22: RURAL | H22: GRT Baja California | I22: ALMACEN ZT VALLE | J22: TELEESCUELA
A23: 02ETK0006H | B23: 513445 | C23: TELEBACHILLERATO COMUNITARIO CORONITAS | D23: BAJA CALIFORNIA | E23: MEXICALI | F23: EJIDO HERIBERTO JARA | G23: RURAL | H23: GRT Baja California | I23: ALMACEN ZT VALLE | J23: TELEESCUELA | K23: Instalado - Operando | L23: 46150
A24: 02ETK0007G | B24: 513463 | C24: TELEBACHILLERATO COMUNITARIO CHIAPAS | D24: BAJA CALIFORNIA | E24: MEXICALI | F24: EJIDO CHIAPAS 2 LAS CACHORAS | G24: RURAL | H24: GRT Baja California | I24: ALMACEN ZT VALLE | J24: TELEESCUELA
A25: 02ETK0008F | B25: 513523 | C25: TBC GONZALEZ ORTEGA | D25: BAJA CALIFORNIA | E25: MEXICALI | F25: GONZALEZ ORTEGA 01 | G25: RURAL | H25: GRT Baja California | I25: ALMACEN ZT VALLE | J25: TELEESCUELA | K25: Instalado - Sin Señal | L25: 46148
A26: 02ETK0009E | B26: 513498 | C26: ENCINAL 09 | D26: BAJA CALIFORNIA | E26: TECATE | F26: ENCINAL | G26: RURAL | H26: GRT Baja California | I26: ALMACEN ZT VALLE | J26: TELEESCUELA
A27: 02ETK0010U | B27: 512955 | C27: TELEBACHILLERATO COMUNITARIO LAS CUMBRES | D27: BAJA CALIFORNIA | E27: TIJUANA | F27: LAS CUMBRES | G27: URBANO | H27: GRT Baja California | I27: ALMACEN ZT VALLE | J27: TELEESCUELA
A28: 02ETK0011T | B28: 513393 | C28: TBC VISTA ENCANTADA | D28: BAJA CALIFORNIA | E28: TIJUANA | F28: TIJUANA | G28: RURAL | H28: GRT Baja California | I28: ALMACEN ZT VALLE | J28: TELEESCUELA
A29: 02ETK0012S | B29: 513383 | C29: GENARO VAZQUEZ | D29: BAJA CALIFORNIA | E29: TIJUANA | F29: TIJUANA | G29: RURAL | H29: GRT Baja California | I29: ALMACEN ZT VALLE | J29: TELEESCUELA
A30: 02ETK0014Q | B30: 513376 | C30: CAMINO VERDE | D30: BAJA CALIFORNIA | E30: TIJUANA | F30: TIJUANA | G30: URBANO | H30: GRT Baja California | I30: ALMACEN ZT VALLE | J30: TELEESCUELA
A31: 02ETK0015P | B31: 513504 | C31: TELEBACHILLERATO COMUNITARIO AJUSCO | D31: BAJA CALIFORNIA | E31: ENSENADA | F31: EJIDO EL AJUSCO | G31: RURAL | H31: GRT Baja California | I31: ALMACEN ZT VALLE | J31: TELEESCUELA
A32: 02ETK0016O | B32: 513506 | C32: TELEBACHILLERATO ARTICULO 115 NUMERO 16 | D32: BAJA CALIFORNIA | E32: ENSENADA | F32: ENSENADA | G32: RURAL | H32: GRT Baja California | I32: ALMACEN ZT VALLE | J32: TELEESCUELA
A33: 02ETV0003Q | B33: 513492 | C33: TELESECUNDARIA NO 3 LIBERTADORES | D33: BAJA CALIFORNIA | E33: TECATE | F33: NUEVA COLONIA HINDU | G33: RURAL | H33: GRT Baja California | I33: ALMACEN ZT VALLE | J33: TELEESCUELA
A34: 02ETV0004P | B34: 513467 | C34: TELESECUNDARIA 4 | D34: BAJA CALIFORNIA | E34: ENSENADA | F34: EJIDO LA MISION | G34: RURAL | H34: GRT Baja California | I34: ALMACEN ZT VALLE | J34: TELEESCUELA
A35: 02ETV0006N | B35: 513426 | C35: TELESECUNDARIA 6 | D35: BAJA CALIFORNIA | E35: TIJUANA | F35: TIJUANA | G35: URBANO | H35: GRT Baja California | I35: ALMACEN ZT VALLE | J35: TELEESCUELA
A36: 02ETV0007M | B36: 513503 | C36: TELESECUNDARIA 44 | D36: BAJA CALIFORNIA | E36: ENSENADA | F36: PUERTA TRAMPA | G36: RURAL | H36: GRT Baja California | I36: ALMACEN ZT VALLE | J36: TELEESCUELA
A37: 02ETV0008L | B37: 513482 | C37: TELESECUNDARIA 8 | D37: BAJA CALIFORNIA | E37: ENSENADA | F37: EJIDO HEROES DE LA INDEPENDENCIA | G37: RURAL | H37: GRT Baja California | I37: ALMACEN ZT VALLE | J37: TELEESCUELA
... A43: 02ETV0019R | B43: 513377 | C43: TELESECUNDARIA NO 27 BENITO JUAREZ | D43: BAJA CALIFORNIA | E43: TIJUANA | F43: TIJUANA | G43: URBANO | H43: GRT Baja California | I43: ALMACEN ZT VALLE | J43: TELEESCUELA
A44: 02ETV0020G | B44: 513477 | C44: TELESECUNDARIA 20 | D44: BAJA CALIFORNIA | E44: ENSENADA | F44: ENSENADA | G44: RURAL | H44: GRT Baja California | I44: ALMACEN ZT VALLE | J44: TELEESCUELA | K44: Instalado - Operando | L44: 46150
A45: 02ETV0021F | B45: 513479 | C45: TELESECUNDARIA 19 | D45: BAJA CALIFORNIA | E45: ENSENADA | F45: ENSENADA | G45: URBANO | H45: GRT Baja California | I45: ALMACEN ZT VALLE | J45: TELEESCUELA
A46: 02ETV0022E | B46: 513505 | C46: TELESECUNDARIA 21 | D46: BAJA CALIFORNIA | E46: ENSENADA | F46: SAN ANTONIO DE LAS MINAS | G46: RURAL | H46: GRT Baja California | I46: ALMACEN ZT VALLE | J46: TELEESCUELA
A47: 02ETV0024C | B47: 513017 | C47: TELESECUNDARIA 23 PABLO PICASSO | D47: BAJA CALIFORNIA | E47: TIJUANA | F47: JARDINES DE LAS CRUCES | G47: URBANO | H47: GRT Baja California | I47: ALMACEN ZT VALLE | J47: TELEESCUELA
...

Sheet GEOREFERENCIAS
A1: CLAVE | B1: LATITUD | C1: LONGITUD
A2: 02DTV0005P | B2: 32.520721 | C2: -116.97346
A3: 02DTV0006O | B3: 30.694012 | C3: -116.00116
A4: 02DTV0009L | B4: 31.827451 | C4: -116.58544
A5: 02DTV0011Z | B5: 30.041074 | C5: -115.73798
A6: 02DTV0012Z | B6: 30.465363 | C6: -115.91858
A7: 02DTV0013Y | B7: 32.467779 | C7: -116.78183
A8: 02DTV0014X | B8: 32.548175 | C8: -116.65021
A9: 02DTV0015W | B9: 31.799397 | C9: -116.59095
A10: 02DTV0016V | B10: 31.287973 | C10: -116.21363
A11: 02DTV0017U | B11: 31.868064 | C11: -116.58861
A12: 02DTV0019S | B12: 32.422114 | C12: -116.88307
A13: 02DTV0021G | B13: 32.526991 | C13: -116.82757
... A4231: 24DTV0749R | B4231: 21.687491 | C4231: -99.499702

Sheet CONSOLIDADO
A1: 📊 CONSOLIDADO TOTAL — PROYECTO PAIG FASE II
A4: GERENCIA (GRT) | B4: TOTAL SITIOS | C4: INST. OPERANDO | D4: INST. SIN SEÑAL | E4: EQ. EN ALMACÉN | F4: PROGRAMADO | G4: VISITADO | H4: SIN INMUEBLE | I4: TOTAL ACTUALIZADO | J4: % AVANCE INST. | K4: % AVANCE GENERAL | L4: PENDIENTE SIN ESTATUS | M4: KITS LOG. ALMACÉN | N4: DIFERENCIA VS INSTALADOS | O4: CANCELADOS
A5: GRT Central | B5: 1130 | C5: =COUNTIF('GRT Central'!K6:K1135,"INSTALADO - OPERANDO") -> 769 | D5: =COUNTIF('GRT Central'!K6:K1135,"INSTALADO - SIN SEÑAL") -> 89 | E5: =MAX(0,ENTREGA_ALMACÉN!C37-CONSOLIDADO!C5-CONSOLIDADO!D5) -> 265 | F5: =COUNTIF('GRT Central'!K6:K1135,"PROGRAMADO") -> 0 | G5: =COUNTIF('GRT Central'!K6:K1135,"VISITADO") -> 20 | H5: =COUNTIF('GRT Central'!K6:K1135,"SIN INMUEBLE") -> 0 | I5: =SUM(C5:H5) -> 1143 | J5: =IF(B5=0,0,(C5+D5)/B5) -> 0.75929204 | K5: =IF(B5=0,0,I5/B5) -> 1.0115044 | L5: =B5-I5 -> -13 | M5: =ENTREGA_ALMACÉN!C37 -> 1123 | N5: =E5-M5 -> -858 | O5: =COUNTIF('GRT Central'!K6:K1135,"CANCELADO") -> 0
A6: GRT Occidente | B6: 779 | C6: =COUNTIF('GRT Occidente'!K6:K784,"INSTALADO - OPERANDO") -> 80 | D6: =COUNTIF('GRT Occidente'!K6:K784,"INSTALADO - SIN SEÑAL") -> 20 | E6: =MAX(0,ENTREGA_ALMACÉN!C38-CONSOLIDADO!C6-CONSOLIDADO!D6) -> 631 | F6: =COUNTIF('GRT Occidente'!K6:K784,"PROGRAMADO") -> 0 | G6: =COUNTIF('GRT Occidente'!K6:K784,"VISITADO") -> 0 | H6: =COUNTIF('GRT Occidente'!K6:K784,"SIN INMUEBLE") -> 0 | I6: =SUM(C6:H6) -> 731 | J6: =IF(B6=0,0,(C6+D6)/B6) -> 0.1283697 | K6: =IF(B6=0,0,I6/B6) -> 0.93838254 | L6: =B6-I6 -> 48 | M6: =ENTREGA_ALMACÉN!C38 -> 731 | N6: =E6-M6 -> -100 | O6: =COUNTIF('GRT Occidente'!K6:K784,"CANCELADO") -> 0
A7: GRT Oriente | B7: 395 | C7: =COUNTIF('GRT Oriente'!K6:K400,"INSTALADO - OPERANDO") -> 72 | D7: =COUNTIF('GRT Oriente'!K6:K400,"INSTALADO - SIN SEÑAL") -> 12 | E7: =MAX(0,ENTREGA_ALMACÉN!C39-CONSOLIDADO!C7-CONSOLIDADO!D7) -> 275 | F7: =COUNTIF('GRT Oriente'!K6:K400,"PROGRAMADO") -> 0 | G7: =COUNTIF('GRT Oriente'!K6:K400,"VISITADO") -> 0 | H7: =COUNTIF('GRT Oriente'!K6:K400,"SIN INMUEBLE") -> 0 | I7: =SUM(C7:H7) -> 359 | J7: =IF(B7=0,0,(C7+D7)/B7) -> 0.21265823 | K7: =IF(B7=0,0,I7/B7) -> 0.90886076 | L7: =B7-I7 -> 36 | M7: =ENTREGA_ALMACÉN!C39 -> 359 | N7: =E7-M7 -> -84 | O7: =COUNTIF('GRT Oriente'!K6:K400,"CANCELADO") -> 0
A8: GRT Valle de México | B8: 735 | C8: =COUNTIF('GRT Valle de México'!K6:K740,"INSTALADO - OPERANDO") -> 74 | D8: =COUNTIF('GRT Valle de México'!K6:K740,"INSTALADO - SIN SEÑAL") -> 3 | E8: =MAX(0,ENTREGA_ALMACÉN!C40-CONSOLIDADO!C8-CONSOLIDADO!D8) -> 460 | F8: =COUNTIF('GRT Valle de México'!K6:K740,"PROGRAMADO") -> 0 | G8: =COUNTIF('GRT Valle de México'!K6:K740,"VISITADO") -> 0 | H8: =COUNTIF('GRT Valle de México'!K6:K740,"SIN INMUEBLE") -> 0 | I8: =SUM(C8:H8) -> 537 | J8: =IF(B8=0,0,(C8+D8)/B8) -> 0.1047619 | K8: =IF(B8=0,0,I8/B8) -> 0.73061224 | L8: =B8-I8 -> 198 | M8: =ENTREGA_ALMACÉN!C40 -> 537 | N8: =E8-M8 -> -77 | O8: =COUNTIF('GRT Valle de México'!K6:K740,"CANCELADO") -> 0
A9: GRT Noroeste | B9: 367 | C9: =COUNTIF('GRT Noroeste'!K6:K372,"INSTALADO - OPERANDO") -> 60 | D9: =COUNTIF('GRT Noroeste'!K6:K372,"INSTALADO - SIN SEÑAL") -> 3 | E9: =MAX(0,ENTREGA_ALMACÉN!C41-CONSOLIDADO!C9-CONSOLIDADO!D9) -> 284 | F9: =COUNTIF('GRT Noroeste'!K6:K372,"PROGRAMADO") -> 0 | G9: =COUNTIF('GRT Noroeste'!K6:K372,"VISITADO") -> 0 | H9: =COUNTIF('GRT Noroeste'!K6:K372,"SIN INMUEBLE") -> 2 | I9: =SUM(C9:H9) -> 349 | J9: =IF(B9=0,0,(C9+D9)/B9) -> 0.17166213 | K9: =IF(B9=0,0,I9/B9) -> 0.95095368 | L9: =B9-I9 -> 18 | M9: =ENTREGA_ALMACÉN!C41 -> 347 | N9: =E9-M9 -> -63 | O9: =COUNTIF('GRT Noroeste'!K6:K372,"CANCELADO") -> 0
A10: GRT Norte | B10: 291 | C10: =COUNTIF('GRT Norte'!K6:K296,"INSTALADO - OPERANDO") -> 19 | D10: =COUNTIF('GRT Norte'!K6:K296,"INSTALADO - SIN SEÑAL") -> 3 | E10: =MAX(0,ENTREGA_ALMACÉN!C42-CONSOLIDADO!C10-CONSOLIDADO!D10) -> 269 | F10: =COUNTIF('GRT Norte'!K6:K296,"PROGRAMADO") -> 0 | G10: =COUNTIF('GRT Norte'!K6:K296,"VISITADO") -> 0 | H10: =COUNTIF('GRT Norte'!K6:K296,"SIN INMUEBLE") -> 0 | I10: =SUM(C10:H10) -> 291 | J10: =IF(B10=0,0,(C10+D10)/B10) -> 0.075601375 | K10: =IF(B10=0,0,I10/B10) -> 1 | L10: =B10-I10 -> 0 | M10: =ENTREGA_ALMACÉN!C42 -> 291 | N10: =E10-M10 -> -22 | O10: =COUNTIF('GRT Norte'!K6:K296,"CANCELADO") -> 0
A11: GRT Noreste | B11: 257 | C11: =COUNTIF('GRT Noreste'!K6:K262,"INSTALADO - OPERANDO") -> 42 | D11: =COUNTIF('GRT Noreste'!K6:K262,"INSTALADO - SIN SEÑAL") -> 0 | E11: =MAX(0,ENTREGA_ALMACÉN!C43-CONSOLIDADO!C11-CONSOLIDADO!D11) -> 203 | F11: =COUNTIF('GRT Noreste'!K6:K262,"PROGRAMADO") -> 0 | G11: =COUNTIF('GRT Noreste'!K6:K262,"VISITADO") -> 1 | H11: =COUNTIF('GRT Noreste'!K6:K262,"SIN INMUEBLE") -> 1 | I11: =SUM(C11:H11) -> 247 | J11: =IF(B11=0,0,(C11+D11)/B11) -> 0.16342412 | K11: =IF(B11=0,0,I11/B11) -> 0.96108949 | L11: =B11-I11 -> 10 | M11: =ENTREGA_ALMACÉN!C43 -> 245 | N11: =E11-M11 -> -42 | O11: =COUNTIF('GRT Noreste'!K6:K262,"CANCELADO") -> 0
A12: GRT Baja California | B12: 276 | C12: =COUNTIF('GRT Baja California'!K6:K281,"INSTALADO - OPERANDO") -> 29 | D12: =COUNTIF('GRT Baja California'!K6:K281,"INSTALADO - SIN SEÑAL") -> 14 | E12: =MAX(0,ENTREGA_ALMACÉN!C44-CONSOLIDADO!C12-CONSOLIDADO!D12) -> 184 | F12: =COUNTIF('GRT Baja California'!K6:K281,"PROGRAMADO") -> 0 | G12: =COUNTIF('GRT Baja California'!K6:K281,"VISITADO") -> 0 | H12: =COUNTIF('GRT Baja California'!K6:K281,"SIN INMUEBLE") -> 0 | I12: =SUM(C12:H12) -> 227 | J12: =IF(B12=0,0,(C12+D12)/B12) -> 0.1557971 | K12: =IF(B12=0,0,I12/B12) -> 0.82246377 | L12: =B12-I12 -> 49 | M12: =ENTREGA_ALMACÉN!C44 -> 227 | N12: =E12-M12 -> -43 | O12: =COUNTIF('GRT Baja California'!K6:K281,"CANCELADO") -> 0
A13: TOTAL GENERAL | B13: =SUM(B5:B12) -> 4230 | C13: =SUM(C5:C12) -> 1145 | D13: =SUM(D5:D12) -> 144 | E13: =SUM(E5:E12) -> 2571 | F13: =SUM(F5:F12) -> 0 | G13: =SUM(G5:G12) -> 21 | H13: =SUM(H5:H12) -> 3 | I13: =SUM(I5:I12) -> 3884 | J13: =IF(B13=0,0,C13/B13) -> 0.27068558 | K13: =IF(B13=0,0,I13/B13) -> 0.91820331 | L13: =SUM(L5:L12) -> 346 | M13: =SUM(M5:M12) -> 3860 | N13: =E13-M13 -> -1289 | O13: =SUM(O5:O12) -> 0

Sheet AVANCE_SEMANAL
A1: 📅 AVANCE SEMANAL AUTOMÁTICO — PROYECTO PAIG FASE II | Semana: Domingo → Sábado
A3: ✅ Los totales por GRT se calculan automáticamente según la FECHA ACTUALIZACIÓN registrada en cada pestaña GRT. Solo actualiza las columnas A (Fecha inicio domingo) — el resto es automático.
A5: SEM. | B5: INICIO (DOM) | C5: FIN (SÁB) | D5: GRT Central | E5: GRT Occidente | F5: GRT Oriente | G5: GRT V. México | H5: GRT Noroeste | I5: GRT Norte | J5: GRT Noreste | K5: GRT Baja Cal. | L5: TOTAL SEMANA | M5: ACUMULADO INST. | N5: % AVANCE ACUM. | O5: NOTAS
A6: 1 | B6: 46096 | C6: 46102 | D6: =SUMPRODUCT(((ISNUMBER('GRT Central'!L6:L1135))*('GRT Central'!L6:L1135>=B6)*('GRT Central'!L6:L1135<=C6))*(('GRT Central'!K6:K1135="INSTALADO - OPERANDO")+('GRT Central'!K6:K1135="INSTALADO - SIN SEÑAL")>0)) -> 16 | E6: =SUMPRODUCT(((ISNUMBER('GRT Occidente'!L6:L784))*('GRT Occidente'!L6:L784>=B6)*('GRT Occidente'!L6:L784<=C6))*(('GRT Occidente'!K6:K784="INSTALADO - OPERANDO")+('GRT Occidente'!K6:K784="INSTALADO - SIN SEÑAL")>0)) -> 0 | F6: =SUMPRODUCT(((ISNUMBER('GRT Oriente'!L6:L400))*('GRT Oriente'!L6:L400>=B6)*('GRT Oriente'!L6:L400<=C6))*(('GRT Oriente'!K6:K400="INSTALADO - OPERANDO")+('GRT Oriente'!K6:K400="INSTALADO - SIN SEÑAL")>0)) -> 0 | G6: =SUMPRODUCT(((ISNUMBER('GRT Valle de México'!L6:L740))*('GRT Valle de México'!L6:L740>=B6)*('GRT Valle de México'!L6:L740<=C6))*(('GRT Valle de México'!K6:K740="INSTALADO - OPERANDO")+('GRT Valle de México'!K6:K740="INSTALADO - SIN SEÑAL")>0)) -> 0 | H6: =SUMPRODUCT(((ISNUMBER('GRT Noroeste'!L6:L372))*('GRT Noroeste'!L6:L372>=B6)*('GRT Noroeste'!L6:L372<=C6))*(('GRT Noroeste'!K6:K372="INSTALADO - OPERANDO")+('GRT Noroeste'!K6:K372="INSTALADO - SIN SEÑAL")>0)) -> 0 | I6: =SUMPRODUCT(((ISNUMBER('GRT Norte'!L6:L296))*('GRT Norte'!L6:L296>=B6)*('GRT Norte'!L6:L296<=C6))*(('GRT Norte'!K6:K296="INSTALADO - OPERANDO")+('GRT Norte'!K6:K296="INSTALADO - SIN SEÑAL")>0)) -> 0 | J6: =SUMPRODUCT(((ISNUMBER('GRT Noreste'!L6:L262))*('GRT Noreste'!L6:L262>=B6)*('GRT Noreste'!L6:L262<=C6))*(('GRT Noreste'!K6:K262="INSTALADO - OPERANDO")+('GRT Noreste'!K6:K262="INSTALADO - SIN SEÑAL")>0)) -> 0 | K6: =SUMPRODUCT(((ISNUMBER('GRT Baja California'!L6:L281))*('GRT Baja California'!L6:L281>=B6)*('GRT Baja California'!L6:L281<=C6))*(('GRT Baja California'!K6:K281="INSTALADO - OPERANDO")+('GRT Baja California'!K6:K281="INSTALADO - SIN SEÑAL")>0)) -> 0 | L6: =SUM(D6:K6) -> 16 | M6: =L6 -> 16 | N6: =IF(M6=0,"",M6/4230) -> 0.0037825059
A7: 2 | B7: 46103 | C7: 46109 | D7: =SUMPRODUCT(((ISNUMBER('GRT Central'!L6:L1135))*('GRT Central'!L6:L1135>=B7)*('GRT Central'!L6:L1135<=C7))*(('GRT Central'!K6:K1135="INSTALADO - OPERANDO")+('GRT Central'!K6:K1135="INSTALADO - SIN SEÑAL")>0)) -> 46 | E7: =SUMPRODUCT(((ISNUMBER('GRT Occidente'!L6:L784))*('GRT Occidente'!L6:L784>=B7)*('GRT Occidente'!L6:L784<=C7))*(('GRT Occidente'!K6:K784="INSTALADO - OPERANDO")+('GRT Occidente'!K6:K784="INSTALADO - SIN SEÑAL")>0)) -> 0 | F7: =SUMPRODUCT(((ISNUMBER('GRT Oriente'!L6:L400))*('GRT Oriente'!L6:L400>=B7)*('GRT Oriente'!L6:L400<=C7))*(('GRT Oriente'!K6:K400="INSTALADO - OPERANDO")+('GRT Oriente'!K6:K400="INSTALADO - SIN SEÑAL")>0)) -> 0 | G7: =SUMPRODUCT(((ISNUMBER('GRT Valle de México'!L6:L740))*('GRT Valle de México'!L6:L740>=B7)*('GRT Valle de México'!L6:L740<=C7))*(('GRT Valle de México'!K6:K740="INSTALADO - OPERANDO")+('GRT Valle de México'!K6:K740="INSTALADO - SIN SEÑAL")>0)) -> 0 | H7: =SUMPRODUCT(((ISNUMBER('GRT Noroeste'!L6:L372))*('GRT Noroeste'!L6:L372>=B7)*('GRT Noroeste'!L6:L372<=C7))*(('GRT Noroeste'!K6:K372="INSTALADO - OPERANDO")+('GRT Noroeste'!K6:K372="INSTALADO - SIN SEÑAL")>0)) -> 0 | I7: =SUMPRODUCT(((ISNUMBER('GRT Norte'!L6:L296))*('GRT Norte'!L6:L296>=B7)*('GRT Norte'!L6:L296<=C7))*(('GRT Norte'!K6:K296="INSTALADO - OPERANDO")+('GRT Norte'!K6:K296="INSTALADO - SIN SEÑAL")>0)) -> 0 | J7: =SUMPRODUCT(((ISNUMBER('GRT Noreste'!L6:L262))*('GRT Noreste'!L6:L262>=B7)*('GRT Noreste'!L6:L262<=C7))*(('GRT Noreste'!K6:K262="INSTALADO - OPERANDO")+('GRT Noreste'!K6:K262="INSTALADO - SIN SEÑAL")>0)) -> 0 | K7: =SUMPRODUCT(((ISNUMBER('GRT Baja California'!L6:L281))*('GRT Baja California'!L6:L281>=B7)*('GRT Baja California'!L6:L281<=C7))*(('GRT Baja California'!K6:K281="INSTALADO - OPERANDO")+('GRT Baja California'!K6:K281="INSTALADO - SIN SEÑAL")>0)) -> 0 | L7: =SUM(D7:K7) -> 46 | M7: =M6+L7 -> 62 | N7: =IF(M7=0,"",M7/4230) -> 0.01465721
A8: 3 | B8: 46110 | C8: 46116 | D8: =SUMPRODUCT(((ISNUMBER('GRT Central'!L6:L1135))*('GRT Central'!L6:L1135>=B8)*('GRT Central'!L6:L1135<=C8))*(('GRT Central'!K6:K1135="INSTALADO - OPERANDO")+('GRT Central'!K6:K1135="INSTALADO - SIN SEÑAL")>0)) -> 52 | E8: =SUMPRODUCT(((ISNUMBER('GRT Occidente'!L6:L784))*('GRT Occidente'!L6:L784>=B8)*('GRT Occidente'!L6:L784<=C8))*(('GRT Occidente'!K6:K784="INSTALADO - OPERANDO")+('GRT Occidente'!K6:K784="INSTALADO - SIN SEÑAL")>0)) -> 0 | F8: =SUMPRODUCT(((ISNUMBER('GRT Oriente'!L6:L400))*('GRT Oriente'!L6:L400>=B8)*('GRT Oriente'!L6:L400<=C8))*(('GRT Oriente'!K6:K400="INSTALADO - OPERANDO")+('GRT Oriente'!K6:K400="INSTALADO - SIN SEÑAL")>0)) -> 0 | G8: =SUMPRODUCT(((ISNUMBER('GRT Valle de México'!L6:L740))*('GRT Valle de México'!L6:L740>=B8)*('GRT Valle de México'!L6:L740<=C8))*(('GRT Valle de México'!K6:K740="INSTALADO - OPERANDO")+('GRT Valle de México'!K6:K740="INSTALADO - SIN SEÑAL")>0)) -> 0 | H8: =SUMPRODUCT(((ISNUMBER('GRT Noroeste'!L6:L372))*('GRT Noroeste'!L6:L372>=B8)*('GRT Noroeste'!L6:L372<=C8))*(('GRT Noroeste'!K6:K372="INSTALADO - OPERANDO")+('GRT Noroeste'!K6:K372="INSTALADO - SIN SEÑAL")>0)) -> 0 | I8: =SUMPRODUCT(((ISNUMBER('GRT Norte'!L6:L296))*('GRT Norte'!L6:L296>=B8)*('GRT Norte'!L6:L296<=C8))*(('GRT Norte'!K6:K296="INSTALADO - OPERANDO")+('GRT Norte'!K6:K296="INSTALADO - SIN SEÑAL")>0)) -> 0 | J8: =SUMPRODUCT(((ISNUMBER('GRT Noreste'!L6:L262))*('GRT Noreste'!L6:L262>=B8)*('GRT Noreste'!L6:L262<=C8))*(('GRT Noreste'!K6:K262="INSTALADO - OPERANDO")+('GRT Noreste'!K6:K262="INSTALADO - SIN SEÑAL")>0)) -> 0 | K8: =SUMPRODUCT(((ISNUMBER('GRT Baja California'!L6:L281))*('GRT Baja California'!L6:L281>=B8)*('GRT Baja California'!L6:L281<=C8))*(('GRT Baja California'!K6:K281="INSTALADO - OPERANDO")+('GRT Baja California'!K6:K281="INSTALADO - SIN SEÑAL")>0)) -> 0 | L8: =SUM(D8:K8) -> 52 | M8: =M7+L8 -> 114 | N8: =IF(M8=0,"",M8/4230) -> 0.026950355
A9: 4 | B9: 46117 | C9: 46123 | D9: =SUMPRODUCT(((ISNUMBER('GRT Central'!L6:L1135))*('GRT Central'!L6:L1135>=B9)*('GRT Central'!L6:L1135<=C9))*(('GRT Central'!K6:K1135="INSTALADO - OPERANDO")+('GRT Central'!K6:K1135="INSTALADO - SIN SEÑAL")>0)) -> 52 | E9: =SUMPRODUCT(((ISNUMBER('GRT Occidente'!L6:L784))*('GRT Occidente'!L6:L784>=B9)*('GRT Occidente'!L6:L784<=C9))*(('GRT Occidente'!K6:K784="INSTALADO - OPERANDO")+('GRT Occidente'!K6:K784="INSTALADO - SIN SEÑAL")>0)) -> 0 | F9: =SUMPRODUCT(((ISNUMBER('GRT Oriente'!L6:L400))*('GRT Oriente'!L6:L400>=B9)*('GRT Oriente'!L6:L400<=C9))*(('GRT Oriente'!K6:K400="INSTALADO - OPERANDO")+('GRT Oriente'!K6:K400="INSTALADO - SIN SEÑAL")>0)) -> 0 | G9: =SUMPRODUCT(((ISNUMBER('GRT Valle de México'!L6:L740))*('GRT Valle de México'!L6:L740>=B9)*('GRT Valle de México'!L6:L740<=C9))*(('GRT Valle de México'!K6:K740="INSTALADO - OPERANDO")+('GRT Valle de México'!K6:K740="INSTALADO - SIN SEÑAL")>0)) -> 0 | H9: =SUMPRODUCT(((ISNUMBER('GRT Noroeste'!L6:L372))*('GRT Noroeste'!L6:L372>=B9)*('GRT Noroeste'!L6:L372<=C9))*(('GRT Noroeste'!K6:K372="INSTALADO - OPERANDO")+('GRT Noroeste'!K6:K372="INSTALADO - SIN SEÑAL")>0)) -> 0 | I9: =SUMPRODUCT(((ISNUMBER('GRT Norte'!L6:L296))*('GRT Norte'!L6:L296>=B9)*('GRT Norte'!L6:L296<=C9))*(('GRT Norte'!K6:K296="INSTALADO - OPERANDO")+('GRT Norte'!K6:K296="INSTALADO - SIN SEÑAL")>0)) -> 0 | J9: =SUMPRODUCT(((ISNUMBER('GRT Noreste'!L6:L262))*('GRT Noreste'!L6:L262>=B9)*('GRT Noreste'!L6:L262<=C9))*(('GRT Noreste'!K6:K262="INSTALADO - OPERANDO")+('GRT Noreste'!K6:K262="INSTALADO - SIN SEÑAL")>0)) -> 0 | K9: =SUMPRODUCT(((ISNUMBER('GRT Baja California'!L6:L281))*('GRT Baja California'!L6:L281>=B9)*('GRT Baja California'!L6:L281<=C9))*(('GRT Baja California'!K6:K281="INSTALADO - OPERANDO")+('GRT Baja California'!K6:K281="INSTALADO - SIN SEÑAL")>0)) -> 0 | L9: =SUM(D9:K9) -> 52 | M9: =M8+L9 -> 166 | N9: =IF(M9=0,"",M9/4230) -> 0.039243499
A10: 5 | B10: 46124 | C10: 46130 | D10: =SUMPRODUCT(((ISNUMBER('GRT Central'!L6:L1135))*('GRT Central'!L6:L1135>=B10)*('GRT Central'!L6:L1135<=C10))*(('GRT Central'!K6:K1135="INSTALADO - OPERANDO")+('GRT Central'!K6:K1135="INSTALADO - SIN SEÑAL")>0)) -> 105 | E10: =SUMPRODUCT(((ISNUMBER('GRT Occidente'!L6:L784))*('GRT Occidente'!L6:L784>=B10)*('GRT Occidente'!L6:L784<=C10))*(('GRT Occidente'!K6:K784="INSTALADO - OPERANDO")+('GRT Occidente'!K6:K784="INSTALADO - SIN SEÑAL")>0)) -> 0 | F10: =SUMPRODUCT(((ISNUMBER('GRT Oriente'!L6:L400))*('GRT Oriente'!L6:L400>=B10)*('GRT Oriente'!L6:L400<=C10))*(('GRT Oriente'!K6:K400="INSTALADO - OPERANDO")+('GRT Oriente'!K6:K400="INSTALADO - SIN SEÑAL")>0)) -> 0 | G10: =SUMPRODUCT(((ISNUMBER('GRT Valle de México'!L6:L740))*('GRT Valle de México'!L6:L740>=B10)*('GRT Valle de México'!L6:L740<=C10))*(('GRT Valle de México'!K6:K740="INSTALADO - OPERANDO")+('GRT Valle de México'!K6:K740="INSTALADO - SIN SEÑAL")>0)) -> 0 | H10: =SUMPRODUCT(((ISNUMBER('GRT Noroeste'!L6:L372))*('GRT Noroeste'!L6:L372>=B10)*('GRT Noroeste'!L6:L372<=C10))*(('GRT Noroeste'!K6:K372="INSTALADO - OPERANDO")+('GRT Noroeste'!K6:K372="INSTALADO - SIN SEÑAL")>0)) -> 0 | I10: =SUMPRODUCT(((ISNUMBER('GRT Norte'!L6:L296))*('GRT Norte'!L6:L296>=B10)*('GRT Norte'!L6:L296<=C10))*(('GRT Norte'!K6:K296="INSTALADO - OPERANDO")+('GRT Norte'!K6:K296="INSTALADO - SIN SEÑAL")>0)) -> 0 | J10: =SUMPRODUCT(((ISNUMBER('GRT Noreste'!L6:L262))*('GRT Noreste'!L6:L262>=B10)*('GRT Noreste'!L6:L262<=C10))*(('GRT Noreste'!K6:K262="INSTALADO - OPERANDO")+('GRT Noreste'!K6:K262="INSTALADO - SIN SEÑAL")>0)) -> 0 | K10: =SUMPRODUCT(((ISNUMBER('GRT Baja California'!L6:L281))*('GRT Baja California'!L6:L281>=B10)*('GRT Baja California'!L6:L281<=C10))*(('GRT Baja California'!K6:K281="INSTALADO - OPERANDO")+('GRT Baja California'!K6:K281="INSTALADO - SIN SEÑAL")>0)) -> 0 | L10: =SUM(D10:K10) -> 105 | M10: =M9+L10 -> 271 | N10: =IF(M10=0,"",M10/4230) -> 0.064066194
A11: 6 | B11: 46131 | C11: 46137 | D11: =SUMPRODUCT(((ISNUMBER('GRT Central'!L6:L1135))*('GRT Central'!L6:L1135>=B11)*('GRT Central'!L6:L1135<=C11))*(('GRT Central'!K6:K1135="INSTALADO - OPERANDO")+('GRT Central'!K6:K1135="INSTALADO - SIN SEÑAL")>0)) -> 84 | E11: =SUMPRODUCT(((ISNUMBER('GRT Occidente'!L6:L784))*('GRT Occidente'!L6:L784>=B11)*('GRT Occidente'!L6:L784<=C11))*(('GRT Occidente'!K6:K784="INSTALADO - OPERANDO")+('GRT Occidente'!K6:K784="INSTALADO - SIN SEÑAL")>0)) -> 0 | F11: =SUMPRODUCT(((ISNUMBER('GRT Oriente'!L6:L400))*('GRT Oriente'!L6:L400>=B11)*('GRT Oriente'!L6:L400<=C11))*(('GRT Oriente'!K6:K400="INSTALADO - OPERANDO")+('GRT Oriente'!K6:K400="INSTALADO - SIN SEÑAL")>0)) -> 0 | G11: =SUMPRODUCT(((ISNUMBER('GRT Valle de México'!L6:L740))*('GRT Valle de México'!L6:L740>=B11)*('GRT Valle de México'!L6:L740<=C11))*(('GRT Valle de México'!K6:K740="INSTALADO - OPERANDO")+('GRT Valle de México'!K6:K740="INSTALADO - SIN SEÑAL")>0)) -> 4 | H11: =SUMPRODUCT(((ISNUMBER('GRT Noroeste'!L6:L372))*('GRT Noroeste'!L6:L372>=B11)*('GRT Noroeste'!L6:L372<=C11))*(('GRT Noroeste'!K6:K372="INSTALADO - OPERANDO")+('GRT Noroeste'!K6:K372="INSTALADO - SIN SEÑAL")>0)) -> 0 | I11: =SUMPRODUCT(((ISNUMBER('GRT Norte'!L6:L296))*('GRT Norte'!L6:L296>=B11)*('GRT Norte'!L6:L296<=C11))*(('GRT Norte'!K6:K296="INSTALADO - OPERANDO")+('GRT Norte'!K6:K296="INSTALADO - SIN SEÑAL")>0)) -> 0 | J11: =SUMPRODUCT(((ISNUMBER('GRT Noreste'!L6:L262))*('GRT Noreste'!L6:L262>=B11)*('GRT Noreste'!L6:L262<=C11))*(('GRT Noreste'!K6:K262="INSTALADO - OPERANDO")+('GRT Noreste'!K6:K262="INSTALADO - SIN SEÑAL")>0)) -> 0 | K11: =SUMPRODUCT(((ISNUMBER('GRT Baja California'!L6:L281))*('GRT Baja California'!L6:L281>=B11)*('GRT Baja California'!L6:L281<=C11))*(('GRT Baja California'!K6:K281="INSTALADO - OPERANDO")+('GRT Baja California'!K6:K281="INSTALADO - SIN SEÑAL")>0)) -> 0 | L11: =SUM(D11:K11) -> 88 | M11: =M10+L11 -> 359 | N11: =IF(M11=0,"",M11/4230) -> 0.084869976
A12: 7 | B12: 46138 | C12: 46144 | D12: =SUMPRODUCT(((ISNUMBER('GRT Central'!L6:L1135))*('GRT Central'!L6:L1135>=B12)*('GRT Central'!L6:L1135<=C12))*(('GRT Central'!K6:K1135="INSTALADO - OPERANDO")+('GRT Central'!K6:K1135="INSTALADO - SIN SEÑAL")>0)) -> 210 | E12: =SUMPRODUCT(((ISNUMBER('GRT Occidente'!L6:L784))*('GRT Occidente'!L6:L784>=B12)*('GRT Occidente'!L6:L784<=C12))*(('GRT Occidente'!K6:K784="INSTALADO - OPERANDO")+('GRT Occidente'!K6:K784="INSTALADO - SIN SEÑAL")>0)) -> 2 | F12: =SUMPRODUCT(((ISNUMBER('GRT Oriente'!L6:L400))*('GRT Oriente'!L6:L400>=B12)*('GRT Oriente'!L6:L400<=C12))*(('GRT Oriente'!K6:K400="INSTALADO - OPERANDO")+('GRT Oriente'!K6:K400="INSTALADO - SIN SEÑAL")>0)) -> 1 | G12: =SUMPRODUCT(((ISNUMBER('GRT Valle de México'!L6:L740))*('GRT Valle de México'!L6:L740>=B12)*('GRT Valle de México'!L6:L740<=C12))*(('GRT Valle de México'!K6:K740="INSTALADO - OPERANDO")+('GRT Valle de México'!K6:K740="INSTALADO - SIN SEÑAL")>0)) -> 13 | H12: =SUMPRODUCT(((ISNUMBER('GRT Noroeste'!L6:L372))*('GRT Noroeste'!L6:L372>=B12)*('GRT Noroeste'!L6:L372<=C12))*(('GRT Noroeste'!K6:K372="INSTALADO - OPERANDO")+('GRT Noroeste'!K6:K372="INSTALADO - SIN SEÑAL")>0)) -> 0 | I12: =SUMPRODUCT(((ISNUMBER('GRT Norte'!L6:L296))*('GRT Norte'!L6:L296>=B12)*('GRT Norte'!L6:L296<=C12))*(('GRT Norte'!K6:K296="INSTALADO - OPERANDO")+('GRT Norte'!K6:K296="INSTALADO - SIN SEÑAL")>0)) -> 0 | J12: =SUMPRODUCT(((ISNUMBER('GRT Noreste'!L6:L262))*('GRT Noreste'!L6:L262>=B12)*('GRT Noreste'!L6:L262<=C12))*(('GRT Noreste'!K6:K262="INSTALADO - OPERANDO")+('GRT Noreste'!K6:K262="INSTALADO - SIN SEÑAL")>0)) -> 0 | K12: =SUMPRODUCT(((ISNUMBER('GRT Baja California'!L6:L281))*('GRT Baja California'!L6:L281>=B12)*('GRT Baja California'!L6:L281<=C12))*(('GRT Baja California'!K6:K281="INSTALADO - OPERANDO")+('GRT Baja California'!K6:K281="INSTALADO - SIN SEÑAL")>0)) -> 1 | L12: =SUM(D12:K12) -> 227 | M12: =M11+L12 -> 586 | N12: =IF(M12=0,"",M12/4230) -> 0.13853428
A13: 8 | B13: 46145 | C13: 46151 | D13: =SUMPRODUCT(((ISNUMBER('GRT Central'!L6:L1135))*('GRT Central'!L6:L1135>=B13)*('GRT Central'!L6:L1135<=C13))*(('GRT Central'!K6:K1135="INSTALADO - OPERANDO")+('GRT Central'!K6:K1135="INSTALADO - SIN SEÑAL")>0)) -> 266 | E13: =SUMPRODUCT(((ISNUMBER('GRT Occidente'!L6:L784))*('GRT Occidente'!L6:L784>=B13)*('GRT Occidente'!L6:L784<=C13))*(('GRT Occidente'!K6:K784="INSTALADO - OPERANDO")+('GRT Occidente'!K6:K784="INSTALADO - SIN SEÑAL")>0)) -> 98 | F13: =SUMPRODUCT(((ISNUMBER('GRT Oriente'!L6:L400))*('GRT Oriente'!L6:L400>=B13)*('GRT Oriente'!L6:L400<=C13))*(('GRT Oriente'!K6:K400="INSTALADO - OPERANDO")+('GRT Oriente'!K6:K400="INSTALADO - SIN SEÑAL")>0)) -> 78 | G13: =SUMPRODUCT(((ISNUMBER('GRT Valle de México'!L6:L740))*('GRT Valle de México'!L6:L740>=B13)*('GRT Valle de México'!L6:L740<=C13))*(('GRT Valle de México'!K6:K740="INSTALADO - OPERANDO")+('GRT Valle de México'!K6:K740="INSTALADO - SIN SEÑAL")>0)) -> 60 | H13: =SUMPRODUCT(((ISNUMBER('GRT Noroeste'!L6:L372))*('GRT Noroeste'!L6:L372>=B13)*('GRT Noroeste'!L6:L372<=C13))*(('GRT Noroeste'!K6:K372="INSTALADO - OPERANDO")+('GRT Noroeste'!K6:K372="INSTALADO - SIN SEÑAL")>0)) -> 63 | I13: =SUMPRODUCT(((ISNUMBER('GRT Norte'!L6:L296))*('GRT Norte'!L6:L296>=B13)*('GRT Norte'!L6:L296<=C13))*(('GRT Norte'!K6:K296="INSTALADO - OPERANDO")+('GRT Norte'!K6:K296="INSTALADO - SIN SEÑAL")>0)) -> 17 | J13: =SUMPRODUCT(((ISNUMBER('GRT Noreste'!L6:L262))*('GRT Noreste'!L6:L262>=B13)*('GRT Noreste'!L6:L262<=C13))*(('GRT Noreste'!K6:K262="INSTALADO - OPERANDO")+('GRT Noreste'!K6:K262="INSTALADO - SIN SEÑAL")>0)) -> 26 | K13: =SUMPRODUCT(((ISNUMBER('GRT Baja California'!L6:L281))*('GRT Baja California'!L6:L281>=B13)*('GRT Baja California'!L6:L281<=C13))*(('GRT Baja California'!K6:K281="INSTALADO - OPERANDO")+('GRT Baja California'!K6:K281="INSTALADO - SIN SEÑAL")>0)) -> 42 | L13: =SUM(D13:K13) -> 650 | M13: =M12+L13 -> 1236 | N13: =IF(M13=0,"",M13/4230) -> 0.29219858
A14: 9 | B14: 46152 | C14: 46158 | D14: =SUMPRODUCT(((ISNUMBER('GRT Central'!L6:L1135))*('GRT Central'!L6:L1135>=B14)*('GRT Central'!L6:L1135<=C14))*(('GRT Central'!K6:K1135="INSTALADO - OPERANDO")+('GRT Central'!K6:K1135="INSTALADO - SIN SEÑAL")>0)) -> 27 | E14: =SUMPRODUCT(((ISNUMBER('GRT Occidente'!L6:L784))*('GRT Occidente'!L6:L784>=B14)*('GRT Occidente'!L6:L784<=C14))*(('GRT Occidente'!K6:K784="INSTALADO - OPERANDO")+('GRT Occidente'!K6:K784="INSTALADO - SIN SEÑAL")>0)) -> 0 | F14: =SUMPRODUCT(((ISNUMBER('GRT Oriente'!L6:L400))*('GRT Oriente'!L6:L400>=B14)*('GRT Oriente'!L6:L400<=C14))*(('GRT Oriente'!K6:K400="INSTALADO - OPERANDO")+('GRT Oriente'!K6:K400="INSTALADO - SIN SEÑAL")>0)) -> 5 | G14: =SUMPRODUCT(((ISNUMBER('GRT Valle de México'!L6:L740))*('GRT Valle de México'!L6:L740>=B14)*('GRT Valle de México'!L6:L740<=C14))*(('GRT Valle de México'!K6:K740="INSTALADO - OPERANDO")+('GRT Valle de México'!K6:K740="INSTALADO - SIN SEÑAL")>0)) -> 0 | H14: =SUMPRODUCT(((ISNUMBER('GRT Noroeste'!L6:L372))*('GRT Noroeste'!L6:L372>=B14)*('GRT Noroeste'!L6:L372<=C14))*(('GRT Noroeste'!K6:K372="INSTALADO - OPERANDO")+('GRT Noroeste'!K6:K372="INSTALADO - SIN SEÑAL")>0)) -> 0 | I14: =SUMPRODUCT(((ISNUMBER('GRT Norte'!L6:L296))*('GRT Norte'!L6:L296>=B14)*('GRT Norte'!L6:L296<=C14))*(('GRT Norte'!K6:K296="INSTALADO - OPERANDO")+('GRT Norte'!K6:K296="INSTALADO - SIN SEÑAL")>0)) -> 5 | J14: =SUMPRODUCT(((ISNUMBER('GRT Noreste'!L6:L262))*('GRT Noreste'!L6:L262>=B14)*('GRT Noreste'!L6:L262<=C14))*(('GRT Noreste'!K6:K262="INSTALADO - OPERANDO")+('GRT Noreste'!K6:K262="INSTALADO - SIN SEÑAL")>0)) -> 16 | K14: =SUMPRODUCT(((ISNUMBER('GRT Baja California'!L6:L281))*('GRT Baja California'!L6:L281>=B14)*('GRT Baja California'!L6:L281<=C14))*(('GRT Baja California'!K6:K281="INSTALADO - OPERANDO")+('GRT Baja California'!K6:K281="INSTALADO - SIN SEÑAL")>0)) -> 0 | L14: =SUM(D14:K14) -> 53 | M14: =M13+L14 -> 1289 | N14: =IF(M14=0,"",M14/4230) -> 0.30472813
A15: 10 | B15: 46159 | C15: 46165 | D15: =SUMPRODUCT(((ISNUMBER('GRT Central'!L6:L1135))*('GRT Central'!L6:L1135>=B15)*('GRT Central'!L6:L1135<=C15))*(('GRT Central'!K6:K1135="INSTALADO - OPERANDO")+('GRT Central'!K6:K1135="INSTALADO - SIN SEÑAL")>0)) -> 0 | E15: =SUMPRODUCT(((ISNUMBER('GRT Occidente'!L6:L784))*('GRT Occidente'!L6:L784>=B15)*('GRT Occidente'!L6:L784<=C15))*(('GRT Occidente'!K6:K784="INSTALADO - OPERANDO")+('GRT Occidente'!K6:K784="INSTALADO - SIN SEÑAL")>0)) -> 0 | F15: =SUMPRODUCT(((ISNUMBER('GRT Oriente'!L6:L400))*('GRT Oriente'!L6:L400>=B15)*('GRT Oriente'!L6:L400<=C15))*(('GRT Oriente'!K6:K400="INSTALADO - OPERANDO")+('GRT Oriente'!K6:K400="INSTALADO - SIN SEÑAL")>0)) -> 0 | G15: =SUMPRODUCT(((ISNUMBER('GRT Valle de México'!L6:L740))*('GRT Valle de México'!L6:L740>=B15)*('GRT Valle de México'!L6:L740<=C15))*(('GRT Valle de México'!K6:K740="INSTALADO - OPERANDO")+('GRT Valle de México'!K6:K740="INSTALADO - SIN SEÑAL")>0)) -> 0 | H15: =SUMPRODUCT(((ISNUMBER('GRT Noroeste'!L6:L372))*('GRT Noroeste'!L6:L372>=B15)*('GRT Noroeste'!L6:L372<=C15))*(('GRT Noroeste'!K6:K372="INSTALADO - OPERANDO")+('GRT Noroeste'!K6:K372="INSTALADO - SIN SEÑAL")>0)) -> 0 | I15: =SUMPRODUCT(((ISNUMBER('GRT Norte'!L6:L296))*('GRT Norte'!L6:L296>=B15)*('GRT Norte'!L6:L296<=C15))*(('GRT Norte'!K6:K296="INSTALADO - OPERANDO")+('GRT Norte'!K6:K296="INSTALADO - SIN SEÑAL")>0)) -> 0 | J15: =SUMPRODUCT(((ISNUMBER('GRT Noreste'!L6:L262))*('GRT Noreste'!L6:L262>=B15)*('GRT Noreste'!L6:L262<=C15))*(('GRT Noreste'!K6:K262="INSTALADO - OPERANDO")+('GRT Noreste'!K6:K262="INSTALADO - SIN SEÑAL")>0)) -> 0 | K15: =SUMPRODUCT(((ISNUMBER('GRT Baja California'!L6:L281))*('GRT Baja California'!L6:L281>=B15)*('GRT Baja California'!L6:L281<=C15))*(('GRT Baja California'!K6:K281="INSTALADO - OPERANDO")+('GRT Baja California'!K6:K281="INSTALADO - SIN SEÑAL")>0)) -> 0 | L15: =SUM(D15:K15) -> 0 | M15: =M14+L15 -> 1289 | N15: =IF(M15=0,"",M15/4230) -> 0.30472813
A16: 11 | B16: 46166 | C16: 46172 | D16: =SUMPRODUCT(((ISNUMBER('GRT Central'!L6:L1135))*('GRT Central'!L6:L1135>=B16)*('GRT Central'!L6:L1135<=C16))*(('GRT Central'!K6:K1135="INSTALADO - OPERANDO")+('GRT Central'!K6:K1135="INSTALADO - SIN SEÑAL")>0)) -> 0 | E16: =SUMPRODUCT(((ISNUMBER('GRT Occidente'!L6:L784))*('GRT Occidente'!L6:L784>=B16)*('GRT Occidente'!L6:L784<=C16))*(('GRT Occidente'!K6:K784="INSTALADO - OPERANDO")+('GRT Occidente'!K6:K784="INSTALADO - SIN SEÑAL")>0)) -> 0 | F16: =SUMPRODUCT(((ISNUMBER('GRT Oriente'!L6:L400))*('GRT Oriente'!L6:L400>=B16)*('GRT Oriente'!L6:L400<=C16))*(('GRT Oriente'!K6:K400="INSTALADO - OPERANDO")+('GRT Oriente'!K6:K400="INSTALADO - SIN SEÑAL")>0)) -> 0 | G16: =SUMPRODUCT(((ISNUMBER('GRT Valle de México'!L6:L740))*('GRT Valle de México'!L6:L740>=B16)*('GRT Valle de México'!L6:L740<=C16))*(('GRT Valle de México'!K6:K740="INSTALADO - OPERANDO")+('GRT Valle de México'!K6:K740="INSTALADO - SIN SEÑAL")>0)) -> 0 | H16: =SUMPRODUCT(((ISNUMBER('GRT Noroeste'!L6:L372))*('GRT Noroeste'!L6:L372>=B16)*('GRT Noroeste'!L6:L372<=C16))*(('GRT Noroeste'!K6:K372="INSTALADO - OPERANDO")+('GRT Noroeste'!K6:K372="INSTALADO - SIN SEÑAL")>0)) -> 0 | I16: =SUMPRODUCT(((ISNUMBER('GRT Norte'!L6:L296))*('GRT Norte'!L6:L296>=B16)*('GRT Norte'!L6:L296<=C16))*(('GRT Norte'!K6:K296="INSTALADO - OPERANDO")+('GRT Norte'!K6:K296="INSTALADO - SIN SEÑAL")>0)) -> 0 | J16: =SUMPRODUCT(((ISNUMBER('GRT Noreste'!L6:L262))*('GRT Noreste'!L6:L262>=B16)*('GRT Noreste'!L6:L262<=C16))*(('GRT Noreste'!K6:K262="INSTALADO - OPERANDO")+('GRT Noreste'!K6:K262="INSTALADO - SIN SEÑAL")>0)) -> 0 | K16: =SUMPRODUCT(((ISNUMBER('GRT Baja California'!L6:L281))*('GRT Baja California'!L6:L281>=B16)*('GRT Baja California'!L6:L281<=C16))*(('GRT Baja California'!K6:K281="INSTALADO - OPERANDO")+('GRT Baja California'!K6:K281="INSTALADO - SIN SEÑAL")>0)) -> 0 | L16: =SUM(D16:K16) -> 0 | M16: =M15+L16 -> 1289 | N16: =IF(M16=0,"",M16/4230) -> 0.30472813
A17: 12 | B17: 46173 | C17: 46179 | D17: =SUMPRODUCT(((ISNUMBER('GRT Central'!L6:L1135))*('GRT Central'!L6:L1135>=B17)*('GRT Central'!L6:L1135<=C17))*(('GRT Central'!K6:K1135="INSTALADO - OPERANDO")+('GRT Central'!K6:K1135="INSTALADO - SIN SEÑAL")>0)) -> 0 | E17: =SUMPRODUCT(((ISNUMBER('GRT Occidente'!L6:L784))*('GRT Occidente'!L6:L784>=B17)*('GRT Occidente'!L6:L784<=C17))*(('GRT Occidente'!K6:K784="INSTALADO - OPERANDO")+('GRT Occidente'!K6:K784="INSTALADO - SIN SEÑAL")>0)) -> 0 | F17: =SUMPRODUCT(((ISNUMBER('GRT Oriente'!L6:L400))*('GRT Oriente'!L6:L400>=B17)*('GRT Oriente'!L6:L400<=C17))*(('GRT Oriente'!K6:K400="INSTALADO - OPERANDO")+('GRT Oriente'!K6:K400="INSTALADO - SIN SEÑAL")>0)) -> 0 | G17: =SUMPRODUCT(((ISNUMBER('GRT Valle de México'!L6:L740))*('GRT Valle de México'!L6:L740>=B17)*('GRT Valle de México'!L6:L740<=C17))*(('GRT Valle de México'!K6:K740="INSTALADO - OPERANDO")+('GRT Valle de México'!K6:K740="INSTALADO - SIN SEÑAL")>0)) -> 0 | H17: =SUMPRODUCT(((ISNUMBER('GRT Noroeste'!L6:L372))*('GRT Noroeste'!L6:L372>=B17)*('GRT Noroeste'!L6:L372<=C17))*(('GRT Noroeste'!K6:K372="INSTALADO - OPERANDO")+('GRT Noroeste'!K6:K372="INSTALADO - SIN SEÑAL")>0)) -> 0 | I17: =SUMPRODUCT(((ISNUMBER('GRT Norte'!L6:L296))*('GRT Norte'!L6:L296>=B17)*('GRT Norte'!L6:L296<=C17))*(('GRT Norte'!K6:K296="INSTALADO - OPERANDO")+('GRT Norte'!K6:K296="INSTALADO - SIN SEÑAL")>0)) -> 0 | J17: =SUMPRODUCT(((ISNUMBER('GRT Noreste'!L6:L262))*('GRT Noreste'!L6:L262>=B17)*('GRT Noreste'!L6:L262<=C17))*(('GRT Noreste'!K6:K262="INSTALADO - OPERANDO")+('GRT Noreste'!K6:K262="INSTALADO - SIN SEÑAL")>0)) -> 0 | K17: =SUMPRODUCT(((ISNUMBER('GRT Baja California'!L6:L281))*('GRT Baja California'!L6:L281>=B17)*('GRT Baja California'!L6:L281<=C17))*(('GRT Baja California'!K6:K281="INSTALADO - OPERANDO")+('GRT Baja California'!K6:K281="INSTALADO - SIN SEÑAL")>0)) -> 0 | L17: =SUM(D17:K17) -> 0 | M17: =M16+L17 -> 1289 | N17: =IF(M17=0,"",M17/4230) -> 0.30472813
